Workbook

Sheet Stage_5_API_50
A1: id | B1: Year | C1: Title | D1: Abstract | E1: include_stage5 | F1: reason_stage5 | G1: has_comparator | H1: detected_comparator | I1: has_primary_outcomes | J1: detected_outcomes | K1: confidence_stage5
A2: J502 | B2: 2019 | C2: Pdb16 Assessment of Cost-Effectiveness of a 0.2 Mcg/Day Fluocinolone Acetonide (Fac) Implant in Patients with Chronic Diabetic Macular Oedema (Dmo) in an Eye with Cataract | D2: Objectives: The fluocinolone acetonide 0.2 mug/day implant (FAc) is effective in improving visual acuity in patients with chronic diabetic macular oedema (cDMO) but is associated with worsening of cataract. A model previously suggested that FAc is cost-effective in patients with cDMO, who have undergone cataract surgery or not. The aim of this study was to update this model and assess the cost-effectiveness of FAc in the subgroup of patients with symptomatic cataract. Method(s): The existing Markov model was designed to assess costs and QALYs over lifetime in patients treated with FAc implant, compared to usual care (UC), consisting of laser photocoagulation and anti-VEGFs from the UK NHS perspective. Unit costs and health state utility values (HSUVs) were updated. The FAc price was NHS list price. HSUVs were obtained from the FAME trial using the VFQ-UI utility index. Best-Corrected Visual Acuity (BCVA) with UC was supposed to be stable. Additional scenarios were considered, with BCVA decreasing over time in UC arm, according to real-world data, and with possibility of administering FAc after cataract surgery in the UC arm. Result(s): New HSUVs ranged from 0.48 for blind patients to 0.91 for patients with perfect vision in both eyes. The FAc strategy was more expensive compared to usual care, by 3,445 per patients over lifetime, and produced more QALYs (+0.247). The incremental cost-effectiveness ratio (ICER) was estimated at 13,932 per QALY gained. The ICER was sensitive to the baseline visual acuity, patients' age and the probability of cataract surgery. The probability of FAc being cost-effective was 66.1% at a threshold of 20,000 per QALY gained. Scenario analyses showed that the efficacy of UC had a strong influence on results, and ICER decreased to 1,686 per QALY gained when BCVA decreased under UC Conclusion(s): The FAc implant is a cost-effective treatment for cDMO in patients with symptomatic cataract. Copyright Ãƒâ€šÃ‚Â© 2019 | E2: TRUE | F2: Uses usual care comparator and measures cost/QALY outcomes. | G2: TRUE | H2: Usual/Standard care | I2: TRUE | J2: ['cost', 'qaly'] | K2: 1
A3: J503 | B3: 2019 | C3: Fluorides for preventing early tooth decay (demineralised lesions) during fixed brace treatment | D3: - Background Early dental decay or demineralised lesions (DLs, also known as white spot lesions) can appear on teeth during fixed orthodontic (brace) treatment. Fluoride reduces decay in susceptible individuals, including orthodontic patients. This review compared various forms of topical fluoride to prevent the development of DLs during orthodontic treatment. This is the second update of the Cochrane Review first published in 2004 and previously updated in 2013. Objectives The primary objective was to evaluate whether topical fluoride reduces the proportion of orthodontic patients with new DLs after fixed appliances. The secondary objectives were to examine the effectiveness of different modes of topical fluoride delivery in reducing the proportions of orthodontic patients with new DLs, as well as the severity of lesions, in terms of number, size and colour. ParticipantÃƒÂ¢Ã¢â€šÂ¬Ã‚Âassessed outcomes, such as perception of DLs, and oral healthÃƒÂ¢Ã¢â€šÂ¬Ã‚Ârelated quality of life data were to be included, as would reports of adverse effects. Search methods Cochrane Oral Health's Information Specialist searched the following databases: Cochrane Oral Health's Trials Register (to 1 February 2019), the Cochrane Central Register of Controlled Trials (CENTRAL; 2019, Issue 1) in the Cochrane Library (searched 1 February 2019), MEDLINE Ovid (1946 to 1 February 2019), and Embase Ovid (1980 to 1 February 2019). The US National Institutes of Health Ongoing Trials Register (ClinicalTrials.gov) and the World Health Organization International Clinical Trials Registry Platform were searched for ongoing trials. No restrictions were placed on the language or date of publication when searching the electronic databases. Selection criteria ParallelÃƒÂ¢Ã¢â€šÂ¬Ã‚Âgroup, randomised controlled trials comparing the use of a fluorideÃƒÂ¢Ã¢â€šÂ¬Ã‚Âcontaining product versus a placebo, no treatment or a different type of fluoride treatment, in which the outcome of enamel demineralisation was assessed at the start and at the end of orthodontic treatment. Data collection and analysis At least two review authors independently, in duplicate, conducted risk of bias assessments and extracted data. Authors of trials were contacted to obtain missing data or to ask for clarification of aspects of trial methodology. Cochrane's statistical guidelines were followed. Main results This update includes 10 studies and contains data from nine studies, comparing eight interventions, involving 1798 randomised participants (1580 analysed). One report contained insufficient information and the authors have been contacted. We assessed two studies as at low risk of bias, six at unclear risk of bias, and two at high risk of bias. Two placebo (nonÃƒÂ¢Ã¢â€šÂ¬Ã‚Âfluoride) controlled studies, at low risk of bias, investigated the professional application of varnish (7700 or 10,000 parts per million (ppm) fluoride (F)), every six weeks and found insufficient evidence of a difference regarding its effectiveness in preventing new DLs (risk ratio (RR) 0.52, 95% confidence interval (CI) 0.14 to 1.93; 405 participants; lowÃƒÂ¢Ã¢â€šÂ¬Ã‚Âcertainty evidence). One placebo (nonÃƒÂ¢Ã¢â€šÂ¬Ã‚Âfluoride) controlled study, at unclear risk of bias, provides a low level of certainty that fluoride foam (12,300 ppm F), professionally applied every two months, may reduce the incidence of new DLs (12% versus 49%) after fixed orthodontic treatment (RR 0.26, 95% CI 0.11 to 0.57; 95 participants). One study, at unclear risk of bias, also provides a low level of certainty that use of a highÃƒÂ¢Ã¢â€šÂ¬Ã‚Âconcentration fluoride toothpaste (5000 ppm F) by patients may reduce the incidence of new DLs (18% versus 27%) compared with a conventional fluoride toothpaste (1450 ppm F) (RR 0.68, 95% CI 0.46 to 1.00; 380 participants). There was no evidence for a difference in the proportions of orthodontic patients with new DLs on the teeth after treatment with fixed orthodontic appliances for the following comparisons:ÃƒÂ¢Ã¢â€šÂ¬Ã‚Â¨ ÃƒÂ¢Ã¢â€šÂ¬Ã‚Â an amine fluoride and stannous fluoride toothpaste/mouthrinse combination versus a sodium fluoride toothpaste/mouthrinse,ÃƒÂ¢Ã¢â€šÂ¬Ã‚Â¨ ÃƒÂ¢Ã¢â€šÂ¬Ã‚Â an amine fluoride gel versus a nonÃƒÂ¢Ã¢â€šÂ¬Ã‚Âfluoride placebo applied by participants at home once a week and by professional application every three months,ÃƒÂ¢Ã¢â€šÂ¬Ã‚Â¨ ÃƒÂ¢Ã¢â€šÂ¬Ã‚Â resinÃƒÂ¢Ã¢â€šÂ¬Ã‚Âmodified glass ionomer cement versus lightÃƒÂ¢Ã¢â€šÂ¬Ã‚Âcured composite resin for bonding orthodontic brackets,ÃƒÂ¢Ã¢â€šÂ¬Ã‚Â¨ ÃƒÂ¢Ã¢â€šÂ¬Ã‚Â a 250 ppm F mouthrinse versus 0 ppm F placebo mouthrinse,ÃƒÂ¢Ã¢â€šÂ¬Ã‚Â¨ ÃƒÂ¢Ã¢â€šÂ¬Ã‚Â the use of an intraoral fluorideÃƒÂ¢Ã¢â€šÂ¬Ã‚Âreleasing glass bead device attached to the brace versus a daily fluoride mouthrinse. The last two comparisons involved studies that were assessed at high risk of bias, because a substantial number of participants were lost to followÃƒÂ¢Ã¢â€šÂ¬Ã‚Âup. Unfortunately, although the internal validity and hence the quality of the studies has improved since the first version of the review, they have compared different interventions; therefore, the findings are only considered to provide low level of certainty, because none has been replicated by followÃƒÂ¢Ã¢â€šÂ¬Ã‚Âup studies, in different settings, to confirm external validity. A patientÃƒÂ¢Ã¢â€šÂ¬Ã‚Âreported outcome, such as concern about the aesthetics of any DLs, was still not included as an outcome in any study. Reports of adverse effects from topical fluoride applications were rare and unlikely to be significant. One study involving fluorideÃƒÂ¢Ã¢â€šÂ¬Ã‚Âcontaining glass beads reported numerous breakages. Authors' conclusions This review found a low level of certainty that 12,300 ppm F foam applied by a professional every 6 to 8 weeks throughout fixed orthodontic treatment, might be effective in reducing the proportion of orthodontic patients with new DLs. In addition, there is a low level of certainty that the patient use of a high fluoride toothpaste (5000 ppm F) throughout orthodontic treatment, might be more effective than a conventional fluoride toothpaste. These two comparisons were based on single studies. There was insufficient evidence of a difference regarding the professional application of fluoride varnish (7700 or 10,000 ppm F). Further adequately powered, randomised controlled trials are required to increase the certainty of these findings and to determine the best means of preventing DLs in patients undergoing fixed orthodontic treatment. The most accurate means of assessing adherence with the use of fluoride products by patients and any possible adverse effects also need to be considered. Future studies should follow up participants beyond the end of orthodontic treatment to determine the effect of DLs on patient satisfaction with treatment. Plain language summary Fluorides for preventing early tooth decay (demineralised lesions) during fixed brace treatment Review question ÃƒÂ¢Ã¢â€šÂ¬Ã‚Â¨ Ugly white or brown marks sometimes appear on the teeth during treatment with braces to straighten teeth. These are due to early tooth decay and usually occur with fixed, gluedÃƒÂ¢Ã¢â€šÂ¬Ã‚Âon 'train track', braces, which make it more difficult to clean the teeth. We know that fluoride in toothpaste helps to prevent tooth decay and think that if extra fluoride is given to people wearing fixed braces, it will protect them from getting these marks. The aim of this Cochrane Oral Health's review was to look at how well fluorides help to prevent early tooth decay during fixed brace treatment and to find out the best way to get fluoride to the teeth. Background ÃƒÂ¢Ã¢â€šÂ¬Ã‚Â¨ Wearing a fixed brace makes it harder for people to keep their teeth clean and may also cause pain. Pain can make it more difficult for people to brush their teeth. This can lead to a buildÃƒÂ¢Ã¢â€šÂ¬Ã‚Âup of dental plaque around the brackets that attach the fixed brace to the teeth, and if the plaque stays on the tooth for long enough, it will cause early tooth decay, which looks like white or brown marks (demineralised lesions, also known as white spot lesions). People often wear braces for 18 months or longer and if the decay is left to progress, it can cause holes, which are sometimes bad enough to need fillings to be done in the teeth. Fluoride helps the tooth to heal, reducing tooth decay in people who are at risk of developing it. People receiving fixed brace treatment may be given different forms of fluoride treatment. It is important to think about how the fluoride gets to the teeth. Does the fluoride need to be placed by a dentist or dental nurse, or can people having treatment with braces apply the fluoride to their own teeth? Study characteristics ÃƒÂ¢Ã¢â€šÂ¬Ã‚Â¨ This review is upÃƒÂ¢Ã¢â€šÂ¬Ã‚ÂtoÃƒÂ¢Ã¢â€šÂ¬Ã‚Âdate as of 1 February 2019. The review includes 10 studies but we could only use the information from nine studies involving 1798 randomised people. We have asked for more information about one study. The review looks at eight different ways of applying fluoride to the teeth. People taking part in the studies were all having treatment with fixed braces. The number of people with new decay on the teeth at end of fixed brace treatment, as well as the amount of decay in each person, were measured and counted. We compared the following treatments:ÃƒÂ¢Ã¢â€šÂ¬Ã‚Â¨ ÃƒÂ¢Ã¢â€šÂ¬Ã‚Â dentist or nurseÃƒÂ¢Ã¢â€šÂ¬Ã‚Âapplied fluoride e.g. varnish, gel or foam,ÃƒÂ¢Ã¢â€šÂ¬Ã‚Â¨ ÃƒÂ¢Ã¢â€šÂ¬Ã‚Â patientÃƒÂ¢Ã¢â€šÂ¬Ã‚Âapplied/used fluoride e.g. toothpaste, mouthwash, gel or foam, andÃƒÂ¢Ã¢â€šÂ¬Ã‚Â¨ ÃƒÂ¢Ã¢â€šÂ¬Ã‚Â materials that release fluoride over time e.g. glues, elastic bands. Key results ÃƒÂ¢Ã¢â€šÂ¬Ã‚Â¨ One study showed that when the dentist applies a foam with a high level of fluoride in it onto the teeth every time the patient is seen, this might reduce the risk of new decay. Another study found that if patients use a toothpaste with a higher level of fluoride than normal, then this might also reduce the risk of new marks on their teeth. No studies have shown that other ways of giving the teeth extra fluoride reduced the number and/or size of new decay on teeth in people wearing fixed braces. Harmful effects of the different ways of giving the teeth more fluoride were not reported in any of the included studies. Certainty of the evidence ÃƒÂ¢Ã¢â€šÂ¬Ã‚Â¨ The level of belief we have in these findings is low, due to the lack of studies testing the same fluorides and showing the same results. We suggest that more, wellÃƒÂ¢Ã¢â€šÂ¬Ã‚Âconducted studies should be done in this area. | E3: TRUE | F3: Uses placebo comparator and measures clinical outcomes. | G3: TRUE | H3: Placebo | I3: TRUE | J3: ['clinical'] | K3: 0.9
A4: J504 | B4: 2019 | C4: Pmh28 Assessing the Life-Cycle Value Added of Second-Generation Antipsychotics in Sweden and the Uk: The Case of Risperidone | D4: To estimate the life-cycle value of risperidone - representative of Second-Generation Antipsychotics- relative to First Generation Antipsychotics to balance the view that cost per Quality-Adjusted Life Year (QALY) at launch are enough to guide access decisions. Study aims to drive the discussion on access and price, through recognition of the dynamic nature of value added by pharmaceutical innovation over the long-run. We estimated the number of patients with schizophrenia treated with risperidone in Sweden and the UK (1994-2017). We collected cost-effectiveness data from the literature of risperidone and haloperidol - representative of First-Generation Antipsychotics. We modelled the life-cycle uptake of risperidone to estimate the life-cycle incremental cost, incremental QALYs and Net monetary Benefit (NMB). We also assessed the life-cycle distribution of the consumer (the payer) and the producer (innovator) surpluses. For the UK, the producer surplus represents around 28% of the total surplus before patent expiration and around 5% after patent expiration. Life-cycle NMB for the health system is estimated at 1,116m. During the life-cycle, the NMB significantly increased in response to two events: (i) the launch of Risperidone Long-Acting Injectable (RLAI); and (ii) generic entry. The ICER was negative (dominant) for the whole period. For Sweden, the producer surplus represents around 6% of the total surplus before patent expiration and around 1% after generic competition. Life-cycle NMB is estimated at 803m, and both NMB and ICER follow the same pattern as in the UK. Analysis shows that health systems appropriated most of the life-cycle value (surplus) generated. This suggests that, considering the entire life-cycle, the value added by SGAs to the system is higher than the value estimated using cost-effectiveness analysis at launch. Pricing and reimbursement decisions should take into account the dynamic nature of pharmaceutical markets and the value added by innovative medicines over the long-run. Copyright Ãƒâ€šÃ‚Â© 2019 | E4: TRUE | F4: Uses comparator and measures cost/QALY outcomes. | G4: TRUE | H4: Other | I4: TRUE | J4: ['cost', 'qaly', 'impact'] | K4: 0.9
A5: J505 | B5: 2019 | C5: Fetal fibronectin testing for reducing the risk of preterm birth | D5: - Background Fetal fibronectin (FFN) is an extracellular matrix glycoprotein localized at the maternalÃƒÂ¢Ã¢â€šÂ¬Ã‚Âfetal interface of the amniotic membranes, between chorion and decidua, where it is concentrated in this area between decidua and trophoblast. In normal conditions, FFN is found at very low levels in cervicovaginal secretions. Levels greater than or equal to 50 ng/mL at or after 22 weeks have been associated with an increased risk of spontaneous preterm birth. In fact, FFN is one of the best predictors of preterm birth in all populations studied so far, and can help in selecting which women are at significant risk for preterm birth. This is an update of a review first published in 2008. Objectives To assess the effectiveness of management based on knowledge of FFN testing results for preventing preterm birth. Search methods For this update, we searched Cochrane Pregnancy and ChildbirthÃƒÂ¢Ã¢â€šÂ¬Ã¢â€žÂ¢s Trials Register (7 September 2018), ClinicalTrials.gov , the WHO International Clinical Trials Registry Platform ( ICTRP ) (7 September 2018), and reference lists of retrieved studies. Selection criteria Randomized controlled trials of pregnant women screened with FFN for risk of preterm birth. Studies included are based exclusively on knowledge of FFN results versus no such knowledge, and we have excluded studies including women with only positive or only negative FFN results. Data collection and analysis Two review authors independently assessed trials for inclusion and risk of bias, extracted data, and checked them for accuracy. The quality of the evidence was assessed using the GRADE approach. Main results We identified 16 trials, of which six were eligible for inclusion. The six included studies randomized 546 women with singleton gestations and threatened preterm labor (PTL) at 23 0/7 to 34 6/7 weeks. A total of 277 women were randomized to knowledge and 269 to no knowledge of FFN. No trials were identified on asymptomatic women or multiple gestations. The risk of bias of included studies was mixed. For selected important outcomes, preterm birth before 37, 34, and 32 weeks, and maternal hospitalization, we graded the quality of the evidence and created a 'Summary of findings' table. For these outcomes, the evidence was graded as mainly low quality due to the imprecision of effect estimates. Management based on knowledge of FFN results may reduce preterm birth before 37 weeks (20.7%) versus controls without such knowledge (29.2%) (risk ratio (RR) 0.72, 95% confidence interval (CI) 0.52 to 1.01; 5 trials; 434 women; lowÃƒÂ¢Ã¢â€šÂ¬Ã‚Âquality evidence). However, management based on knowledge of FFN results may make little or no difference to preterm birth before 34 (RR 1.09, 95% CI 0.54 to 2.18; 4 trials; 357 women; lowÃƒÂ¢Ã¢â€šÂ¬Ã‚Âquality evidence) or maternal hospitalization (RR 1.06, 95% CI 0.79 to 1.43; 5 trials; 441 women; lowÃƒÂ¢Ã¢â€šÂ¬Ã‚Âquality evidence). The evidence for preterm birth before 32 weeks is uncertain because the quality was found to be very low (average RR 0.79, 95% CI 0.16 to 3.96; 4 trials; 357 women; very lowÃƒÂ¢Ã¢â€šÂ¬Ã‚Âquality evidence). For all other outcomes, for which there were available data (preterm birth less than 28 weeks; gestational age at delivery (weeks); birthweight less than 2500 g; perinatal death; tocolysis; steroids for fetal lung maturity; time to evaluate; respiratory distress syndrome; neonatal intensive care unit (NICU) admission; and NICU days), knowledge of FFN results may make little or no difference to the outcomes. Authors' conclusions The evidence from this review suggests that management based on knowledge of FFN results may reduce preterm birth before 37 weeks. However, our confidence in this result is limited as the evidence was found to be of low quality. Effects on other substantive outcomes are uncertain due to serious concerns in study design, inconsistency, and imprecision of effect estimates. No trials were identified on asymptomatic women, or multiple gestations. Future studies are needed that include specific populations (e.g. singleton gestations with symptoms of preterm labor), a study gro p managed with a protocol based on the FFN results, and that report not only maternal but also important perinatal outcomes. CostÃƒÂ¢Ã¢â€šÂ¬Ã‚Âeffectiveness analyses are also needed. Plain language summary Fetal fibronectin testing for reducing the risk of preterm birth What is the issue? To assess the effectiveness of management of pregnant women based on a knowledge of fetal fibronectin test results for preventing preterm birth, compared with not having that knowledge. Fetal fibronectin (FFN) acts as a ÃƒÂ¢Ã¢â€šÂ¬Ã‹Å“glueÃƒÂ¢Ã¢â€šÂ¬Ã¢â€žÂ¢ between the pregnancy and the uterus. Normally very low levels of FFN can be found in secretions of the vagina and cervix. Raised levels at or after 22 weeks have been associated with an increased risk of spontaneous preterm birth. Why is this important? Preterm birth before 37 weeks is the main cause of sickness and death for newborn infants. Most women who give birth preterm have preterm labor symptoms such as contractions but many of the women with symptoms go on to deliver at term (37 weeks or more). Fetal fibronectin (FFN) is a test that can identify the women with symptoms of preterm labor who are most at risk for preterm birth. The level of FFN is measured in secretions from the vagina or cervix. What evidence did we find? We found six randomised controlled studies involving 546 women who were pregnant with one baby and were showing signs of preterm labor at between 23 to 34 weeks' gestation. We graded the following evidence as mainly low quality because of the low number of women in the studies and a wide variation in findings. We found that the number of births before 37 weeks may be slightly reduced when women and their doctors know the results of the FFN test (20.7% versus 29.2%; 5 trials; 434 women). However, knowledge of FFN results may make little or no difference for the other outcomes with available data, including: maternal hospitalization (5 trials; 441 women); use of uterine relaxants (tocolysis) to try to prevent labor; earlier preterm births; womenÃƒÂ¢Ã¢â€šÂ¬Ã¢â€žÂ¢s gestational age at delivery; babies with a birthweight less than 2500 g; newborn deaths; the number of babies with respiratory distress syndrome; giving steroids to mature the unborn babiesÃƒÂ¢Ã¢â€šÂ¬Ã¢â€žÂ¢ lungs; and number of days in a neonatal intensive care unit (NICU). What does this mean? This review of six studies did not find enough evidence to say whether or not the FFN test should be used in the management of women showing signs of preterm labor. A screening test such as FFN can only be considered effective if interventions based on the screening results, such as giving drugs to relax the uterus, reduce the number of preterm births. Further research should be encouraged. | E5: TRUE | F5: Uses a comparator and measures clinical outcomes. | G5: TRUE | H5: No intervention/Do nothing | I5: TRUE | J5: ['clinical', 'impact'] | K5: 0.9
A6: J508 | B6: 2019 | C6: Adalimumab for non-infectious uveitis: Is it cost-effective? | D6: Background/Aims: Uveitis is inflammation inside the eye. Our objective was to assess the cost-effectiveness of adalimumab compared with current practice (immunosuppressants and systemic corticosteroids) in patients with non-infectious intermediate, posterior or panuveitis and to identify areas for future research. Method(s): A Markov model was built to estimate costs and benefits of the interventions. Systematic reviews were performed to identify the available relevant clinical and cost-effectiveness evidence. Data collected in two key randomised controlled trials (VISUAL I and VISUAL II) were used to estimate the interventions' effectiveness compared with the trials' comparator arms (placebo plus limited current practice (LCP)). The analysis was performed from the National Health Service and Personal Social Services perspective. Costs were calculated based on standard UK sources. Result(s): The estimated incremental cost-effectiveness ratios (ICERs) of adalimumab versus LCP for the base case are 92 600 and 318 075 per quality-adjusted life year (QALY) gained for active and inactive uveitis, respectively. In sensitivity analyses, the ICER varied from 15 579 to 120 653 and 35 642 to 800 775 per QALY for active and inactive uveitis. Conclusion(s): The estimated ICERs of adalimumab versus LCP are above generally accepted thresholds for cost-effectiveness in the UK. Adalimumab may be more cost-effective in patients with active uveitis at greater risk of blindness. However, there is an unmet need for additional primary data to provide more reliable estimates in several important areas, including effectiveness of adalimumab versus current practice (instead of LCP), incidence of long-term blindness, adalimumab effectiveness in avoiding blindness, and rates and time to remission while on adalimumab. Copyright Ãƒâ€šÃ‚Â© 2019 Author(s). | E6: TRUE | F6: Uses placebo comparator and measures cost-effectiveness (QALY). | G6: TRUE | H6: Placebo | I6: TRUE | J6: ['cost', 'qaly'] | K6: 1
A7: J509 | B7: 2019 | C7: Burden of varicella complications in secondary care, England, 2004 to 2017 | D7: Background: Strategies to control varicella vary across Europe. Evidence from established programmes has prompted the United Kingdom to re-evaluate the need for universal vaccination. The burden of complicated varicella is a key parameter in the cost-effectiveness analysis. Aim(s): Our objective was to estimate the burden of complicated varicella in England. Method(s): This electronic health record surveillance study used data from all NHS hospitals in England to identify varicella admissions between 2004 and 2017. The incidence of pre-defined complications of varicella was estimated using ICD-10 codes. Inpatient costs were calculated based on the payment rules for providers of NHS services. Result(s): There were 61,024 admissions with varicella between 2004 and 2017 and 38.1% had a recognised varicella complication. Incidence of hospitalisation increased by 25% and the proportion with complicated varicella by 24% from 2004/05 to 2016/17. The most common complications were bacterial skin infections (11.25%), pneumonia (4.82%), febrile convulsions (3.39%) and encephalitis (2.44%). Complication rates were higher in older age groups and the type of complications more severe. Length of stay for complicated varicella was 3.1 times longer than for uncomplicated varicella and inpatient costs were 72% greater. Conclusion(s): Complicated varicella has a substantial health and economic burden. These data together with data on impact on quality of life are important in informing the cost-effectiveness analysis of universal varicella vaccination. Copyright Ãƒâ€šÃ‚Â© 2019 European Centre for Disease Prevention and Control (ECDC). All rights reserved. | E7: FALSE | F7: No comparator group detected | G7: FALSE | H7: Unknown | I7: TRUE | J7: ['cost', 'impact'] | K7: 0.9
A8: J510 | B8: 2019 | C8: Treatment for hepatorenal syndrome in people with decompensated liver cirrhosis: a network metaÃƒÂ¢Ã¢â€šÂ¬Ã‚Âanalysis | D8: - Background Hepatorenal syndrome is defined as renal failure in people with cirrhosis in the absence of other causes. In addition to supportive treatment such as albumin to restore fluid balance, the other potential treatments include systemic vasoconstrictor drugs (such as vasopressin analogues or noradrenaline), renal vasodilator drugs (such as dopamine), transjugular intrahepatic portosystemic shunt (TIPS), and liver support with molecular adsorbent recirculating system (MARS). There is uncertainty over the best treatment regimen for hepatorenal syndrome. Objectives To compare the benefits and harms of different treatments for hepatorenal syndrome in people with decompensated liver cirrhosis. Search methods We searched CENTRAL, MEDLINE, Embase, Science Citation Index Expanded, World Health Organization International Clinical Trials Registry Platform, and trial registers until December 2018 to identify randomised clinical trials on hepatorenal syndrome in people with cirrhosis. Selection criteria We included only randomised clinical trials (irrespective of language, blinding, or publication status) in adults with cirrhosis and hepatorenal syndrome. We excluded randomised clinical trials in which participants had previously undergone liver transplantation. Data collection and analysis Two authors independently identified eligible trials and collected data. The outcomes for this review included mortality, serious adverse events, any adverse events, resolution of hepatorenal syndrome, liver transplantation, and other decompensation events. We performed a network metaÃƒÂ¢Ã¢â€šÂ¬Ã‚Âanalysis with OpenBUGS using Bayesian methods and calculated the odds ratio (OR), rate ratio, hazard ratio (HR), and mean difference (MD) with 95% credible intervals (CrI) based on an availableÃƒÂ¢Ã¢â€šÂ¬Ã‚Âcase analysis, according to National Institute of Health and Care Excellence Decision Support Unit guidance. Main results We included a total of 25 trials (1263 participants; 12 interventions) in the review. TwentyÃƒÂ¢Ã¢â€šÂ¬Ã‚Âthree trials (1185 participants) were included in one or more outcomes. All the trials but two were at high risk of bias, and all the evidence was of low or very low certainty. The trials included participants with liver cirrhosis of varied aetiologies as well as a mixture of type I hepatorenal syndrome only, type II hepatorenal syndrome only, or people with both type I and type II hepatorenal syndrome. Participant age ranged from 42 to 60 years, and the proportion of females ranged from 5.8% to 61.5% in the trials that reported this information. The followÃƒÂ¢Ã¢â€šÂ¬Ã‚Âup in the trials ranged from one week to six months. Overall, 59% of participants died during this period and about 35% of participants recovered from hepatorenal syndrome. The most common interventions compared were albumin plus terlipressin, albumin plus noradrenaline, and albumin alone. There was no evidence of a difference in mortality (22 trials; 1153 participants) at maximal followÃƒÂ¢Ã¢â€šÂ¬Ã‚Âup between the different interventions. None of the trials reported healthÃƒÂ¢Ã¢â€šÂ¬Ã‚Ârelated quality of life. There was no evidence of differences in the proportion of people with serious adverse events (three trials; 428 participants), number of participants with serious adverse events per participant (two trials; 166 participants), proportion of participants with any adverse events (four trials; 402 participants), the proportion of people who underwent liver transplantation at maximal followÃƒÂ¢Ã¢â€šÂ¬Ã‚Âup (four trials; 342 participants), or other features of decompensation at maximal followÃƒÂ¢Ã¢â€šÂ¬Ã‚Âup (one trial; 466 participants). Five trials (293 participants) reported number of any adverse events, and five trials (219 participants) reported treatment costs. Albumin plus noradrenaline had fewer numbers of adverse events per participant (rate ratio 0.51, 95% CrI 0.28 to 0.87). Eighteen trials (1047 participants) reported recovery from hepatorenal syndrome (as per definition of hepatorenal syndrome). In terms of recovery from hepatorenal syndrome, in the direct comparisons, albumin plus midodrine plus octreotide and albumin plus octreotide had lower recovery from hepatorenal syndrome than albumin plus terlipressin (HR 0.04; 95% CrI 0.00 to 0.25 and HR 0.26, 95% CrI 0.07 to 0.80 respectively). There was no evidence of differences between the groups in any of the other direct comparisons. In the network metaÃƒÂ¢Ã¢â€šÂ¬Ã‚Âanalysis, albumin and albumin plus midodrine plus octreotide had lower recovery from hepatorenal syndrome compared with albumin plus terlipressin. Funding: two trials were funded by pharmaceutical companies; five trials were funded by parties who had no vested interest in the results of the trial; and 18 trials did not report the source of funding. Authors' conclusions Based on very lowÃƒÂ¢Ã¢â€šÂ¬Ã‚Âcertainty evidence, there is no evidence of benefit or harm of any of the interventions for hepatorenal syndrome with regards to the following outcomes: allÃƒÂ¢Ã¢â€šÂ¬Ã‚Âcause mortality, serious adverse events (proportion), number of serious adverse events per participant, any adverse events (proportion), liver transplantation, or other decompensation events. LowÃƒÂ¢Ã¢â€šÂ¬Ã‚Âcertainty evidence suggests that albumin plus noradrenaline had fewer 'any adverse events per participant' than albumin plus terlipressin. LowÃƒÂ¢Ã¢â€šÂ¬Ã‚Â or very lowÃƒÂ¢Ã¢â€šÂ¬Ã‚Âcertainty evidence also found that albumin plus midodrine plus octreotide and albumin alone had lower recovery from hepatorenal syndrome compared with albumin plus terlipressin. Future randomised clinical trials should be adequately powered; employ blinding, avoid postÃƒÂ¢Ã¢â€šÂ¬Ã‚Ârandomisation dropouts or planned crossÃƒÂ¢Ã¢â€šÂ¬Ã‚Âovers (or perform an intentionÃƒÂ¢Ã¢â€šÂ¬Ã‚ÂtoÃƒÂ¢Ã¢â€šÂ¬Ã‚Âtreat analysis); and report clinically important outcomes such as mortality, healthÃƒÂ¢Ã¢â€šÂ¬Ã‚Ârelated quality of life, adverse events, and recovery from hepatorenal syndrome. Albumin plus noradrenaline and albumin plus terlipressin appear to be the interventions that should be compared in future trials. Plain language summary Treatment of hepatorenal syndrome What is the aim of this Cochrane review? To find out the best treatment for decreased kidney function (hepatorenal syndrome) in people with liver cirrhosis (a form of advanced liver disease with scarring of the liver) with complications. The authors collected and analysed all relevant studies to answer this question and found 25 randomised controlled trials (participants receive the treatment based on method similar to coin toss or lottery; this is to ensure that the people who receive the different treatments are similar in all aspects except the treatment, so that any differences in the results between the treatments can be attributed to the treatment rather than differences in the type of people who received the treatment). During analysis of data, authors used standard Cochrane techniques, which allows comparison of two treatments at a time. Authors also used advanced techniques, that allow comparison of many treatments at the same time (usually referred as 'network metaÃƒÂ¢Ã¢â€šÂ¬Ã‚Âanalysis' or 'multiple treatment comparisons'). The aim is to gather reliable evidence on the relative benefits and harms of the different treatments. Date of literature search ÃƒÂ¢Ã¢â€šÂ¬Ã‚Â¨ December 2018 Key messages ÃƒÂ¢Ã¢â€šÂ¬Ã‚Â¨ Only two studies were conducted well. The remaining studies had one or more flaws. Therefore, there is high uncertainty in the results of the analysis. The authors could not recommend one treatment over another on the basis of risk of death, serious complications, percentage of people who developed any complication, percentage of participants who underwent liver transplantation (replacement of a diseased liver with a healthy one), or the number of other liver failure events. HealthÃƒÂ¢Ã¢â€šÂ¬Ã‚Ârelated quality of life was not reported in any of the trials. The number of complications of any severity was lower with albumin plus noradrenaline than albumin plus terlipressin. Recovery from hepatorenal syndrome may be lower with albumin plus midodrine plus octreotide and albumin alone than albumin plus terlipressin and albumin plus noradrenaline. Funding source was unclear in 18 studies. Industrial organisations funded two studies and the remaining five studies did not receive any funding from industrial organisations. What was studied in the review? This review studied people of any sex, age, and origin, having advanced liver disease due to various causes, and who had developed hepatorenal syndrome. People were administered different treatments. The review authors excluded studies with liverÃƒÂ¢Ã¢â€šÂ¬Ã‚Âtransplanted participants. Participants age, when reported, ranged from 42 to 60 years. The number of females ranged from 6 to 62 out of 100 in the studies that reported this information. The main treatments compared were albumin alone, albumin plus terlipressin, and albumin plus noradrenaline. The authors gathered and analysed data on death, quality of life, serious and nonÃƒÂ¢Ã¢â€šÂ¬Ã‚Âserious complications, time to liver transplantation, recovery from hepatorenal syndrome, and disappearance of symptoms. What were the main results of the review? The 25 studies included a small number of participants (1263 participants). Study data were sparse. TwentyÃƒÂ¢Ã¢â€šÂ¬Ã‚Âthree studies with 1185 participants provided data for analyses. The followÃƒÂ¢Ã¢â€šÂ¬Ã‚Âup in the trials ranged from one week to six months. The review shows that: ÃƒÂ¢Ã¢â€šÂ¬Ã‚Â About 60 out of every 100 people died within three months, and 35 out of every 100 people recovered from hepatorenal syndrome. ÃƒÂ¢Ã¢â€šÂ¬Ã‚Â The provided treatment may make no difference to the percentage of people who died or developed serious complications, number of serious complications per person, percentage of people who developed complications of any severity, or the percentage of people undergoing liver transplantation. ÃƒÂ¢Ã¢â€šÂ¬Ã‚Â None of the trials reported healthÃƒÂ¢Ã¢â€šÂ¬Ã‚Ârelated quality of life. ÃƒÂ¢Ã¢â€šÂ¬Ã‚Â The number of complications of any severity was lower with albumin plus noradrenaline than albumin plus terlipressin. ÃƒÂ¢Ã¢â€šÂ¬Ã‚Â Recovery from hepatorenal syndrome may be lower with albumin plus midodrine plus octreotide and albumin alone than albumin plus terlipressin and albumin plus noradrenaline. ÃƒÂ¢Ã¢â€šÂ¬Ã‚Â We have very low confidence in the overall results. ÃƒÂ¢Ã¢â€šÂ¬Ã‚Â Future trials with proper design and quality are needed to clarify the best treatment for people with advanced liver disease having hepatorenal syndrome. | E8: TRUE | F8: Uses comparator and measures clinical outcomes. | G8: TRUE | H8: Other | I8: TRUE | J8: ['clinical', 'safety', 'impact'] | K8: 0.9
A9: J511 | B9: 2019 | C9: Switching from originator infliximab to CT-P13: Single-centre experience from the UK | D9: Background: The infliximab biosimilar (CT-P13) received market authorisation for inflammatory bowel disease in late 2016 with the aim of reducing cost and increasing access to therapy. The prospect of 'switching' patients from originator to CT-P13 has concerned clinicians. #8232;We present an experience of 'switching' from originator infliximab (IFX-O) to CT-P13 and present efficacy, safety, and immunogenicity data from our cohort. Method(s): We performed a retrospective review of patients switched from IFX-O to CT-P13. Disease demographics, clinical course and outcomes were analysed from electronic case records at a median of 8 months and at last follow-up at 13 months. Result(s): Ninety-six patients (35 females) were 'switched' from IFX-O to CT-P13. Of these 44 had Ulcerative colitis (UC) and 52 had Crohn's disease (CD) with a mean age at diagnosis of 34.7 years (median = 33, IQR = 24.5). Montreal phenotype for UC was E1 = 1, E2 = 16, E3 = 27 and for CD (L1 = 10, L2 = 12 , L3 = 29, L4 = 1) and (B1 = 27, #8232;B2 = 14 , B3 = 11), 9 patients had perianal disease. Mean duration of IFX-O treatment was 49. 8 months (median = 44, IQR = 52) and on CT-P13 11.5 months (median 13). At switch, 76 patients had a normal CRP (UC = 33, CD = 43), and in 15 patients it was elevated (UC = 10, CD = 5). At 8 months, 80 patients remained in biochemical remission (UC = 35, CD = 45 ) and in 14 patients (UC = 8, CD = 6 ) CRP increased. Seventy-two patients (UC = 34, CD = 38 ) were in clinical remission (pMayo < 2 and HBI < 5). Of 51 patients (UC = 21, CD = 30) undergoing endoscopic assessment, 31 achieved mucosal healing (UC = 13, CD = 18). At 13 months, 69 patients remained on CT-P13. Twenty-seven discontinued the drug due to immunogenicity (n = 10), loss of response (n = 5), surgery (n = 5), remission (n = 5) , side effects (n = 2 ), and 1 patient died of hospital acquired pneumonia. 39 out of 96 patients had therapeutic drug levels checked within 13 months of switch, of whom 27 had sub-therapeutic levels (below 4 mug/ml). Antibodies to Infliximab were seen in 15 of 39 patients (38.5%), of whom 8 were switched to an alternative biologic, 2 had dose escalation (10 mg/kg IFX), 4 patients stopped IFX with no other intervention, and 1 person continued treatment at same dose with low antibody titre of 6. Conclusion(s): Biosimilar IFX (CT-P13) was well tolerated. Clinical efficacy and loss of response rates with CT-P13 appears to be similar to IFX-O. This holds promise for a wider adoption of 'switching' to fulfil the purported aims of wider access to treatment at a lower cost. | E9: FALSE | F9: No comparison group detected | G9: FALSE | H9: Unknown | I9: TRUE | J9: ['clinical', 'safety', 'impact'] | K9: 0.9
A10: J512 | B10: 2019 | C10: Switching from originator infliximab to CT-P13: A UK single centre experience | D10: Introduction and Aims The infliximab biosimilar (CT-P13) received market authorization for inflammatory bowel disease in late 2016 with the aim of reducing cost and increasing access to therapy. The prospect of 'switching' patients from originator to CT-P13 has concerned clinicians.We present an experience of 'switching' from originator infliximab (IFX-O) to CT-P13 and present efficacy, safety and immunogenicity data from our cohort. Methods We performed a retrospective review of patients switched from IFX-O to CT-P13 at our center. Disease demographics, clinical course and outcomes were analysed from electronic case records at 8 months and at last follow-up at 13 months. Results Ninety-six patients (35 female) were 'switched' from IFX-O to CT-P13. Of these 44 had Ulcerative colitis (UC) and 52 had Crohn's disease (CD) with a mean age at diagnosis of 34.7 years (median= 33, IQR = 24.5). Montreal phenotype for UC was Proctitis( E1) = 1, Left sided(E2) = 16,Pancolitis ( E3) = 27 and for CD (L1 = 10,L2 = 12, L3 = 29, L4 = 1) and ( B1 = 27,B2 = 14, B3 = 11), 9 patients had perianal disease. Mean duration of IFX-O treatment before switching was 49.8 months (median = 44, IQR = 52) and on CT-P13 11.5 months (median 13). At switch, 76 patients had a normal CRP (UC = 33, CD = 43), and in 15 patients it was elevated (UC= 10, CD= 5). At 8 months, 72 patients (UC = 34, CD = 38) were in clinical remission (pMayo < 2 and HBI < 5) and 80 patients remained in biochemical remission (UC= 35,CD= 45). In 14 patients (UC= 8,CD= 6 ) CRP increased. Of 51 patients (UC= 21, CD= 30) undergoing endoscopic assessment, 31 achieved mucosal healing (UC =13, CD= 18). At 13 months 69 patients remained on CT-P13. 28% discontinued the drug due to immunogenicity(n=10), loss of response(n=5), surgery(n=5), remission (n=5), side effects (n=2) and 1 patient died of hospital acquired pneumonia. 39 out of 96 patients had therapeutic drug levels checked within a median of 13 months from switch. 27 had sub-therapeutic levels (below 4ug/ml ),11 of which were switched to another biologic, 5 referred for surgery, 4 had dose escalated to 10 mg/kg, 5 continued CT-P13( 4 with no antibodies seen and 1 with antibodies of 127),one had immunomodulator added and another stopped CT-P13 being in remission. Antibodies to Infliximab were seen in 15 of 39 patients (38.5%), of whom 8 were switched to an alternative biologic, 2 had dose escalation (10 mg/kg IFX),4 patients stopped IFX with no other intervention and 1 person continued treatment with low antibody titre of 6. Discussion Biosimilar IFX (CT-P13) was well tolerated. Clinical efficacy and loss of response rates with CT-P13 appears to be similar to IFX-O. This holds promise for a wider adoption of 'switching' to fulfil the purported aims of wider access to treatment at a lower cost. | E10: FALSE | F10: No comparison group detected | G10: FALSE | H10: Unknown | I10: TRUE | J10: ['clinical', 'safety'] | K10: 0.9
A11: J514 | B11: 2019 | C11: ÃƒÂ¢Ã¢â€šÂ¬Ã¢â‚¬Â¹Primary closure versus delayed or no closure for traumatic wounds due to mammalian bite | D11: - Background Mammalian bites are a common presentation in emergency and primary healthcare facilities across the world. The World Health Organization recommends postponing the suturing of a bite wound but this has not been evaluated through a systematic review. Objectives To assess the effects of primary closure compared with delayed closure or no closure for mammalian bite wounds. Search methods In July 2019 we searched the Cochrane Wounds Specialised Register; the Cochrane Central Register of Controlled Trials (CENTRAL); Ovid MEDLINE (including InÃƒÂ¢Ã¢â€šÂ¬Ã‚ÂProcess & Other NonÃƒÂ¢Ã¢â€šÂ¬Ã‚ÂIndexed Citations); Ovid Embase and EBSCO CINAHL Plus. We also searched clinical trials registries for ongoing and unpublished studies, and scanned reference lists of relevant included studies as well as reviews, metaÃƒÂ¢Ã¢â€šÂ¬Ã‚Âanalyses and health technology reports to identify additional studies. There were no restrictions with respect to language, date of publication or study setting. Selection criteria We included randomised controlled trials which compared primary closure with delayed or no closure for traumatic wounds due to mammalian bite. Data collection and analysis Two review authors independently screened titles, abstracts and fullÃƒÂ¢Ã¢â€šÂ¬Ã‚Âtext publications, applied the inclusion criteria, and extracted data. We pooled data using a randomÃƒÂ¢Ã¢â€šÂ¬Ã‚Âeffects model, as appropriate. We used the Cochrane 'Risk of bias' tool and assessed the certainty of the evidence using the GRADE approach. Main results We found three trials (878 participants) that compared primary closure with no closure for dog bites and one trial (120 participants) that compared primary closure with delayed closure. No other mammalian bite studies were identified. The trials were from the UK (one trial), Greece (one trial) and China (two trials). Overall, participants from both sexes and all age groups were represented. We are uncertain whether primary closure improves the proportion of wounds which are infectionÃƒÂ¢Ã¢â€šÂ¬Ã‚Âfree compared with no closure, as the certainty of evidence for this outcome was judged to be very low (risk ratio (RR) 1.01, 95% confidence interval (CI) 0.97 to 1.05; 2 studies, 782 participants; I 2 = 0%). We downgraded the evidence by one level for high risk of bias and two levels for imprecision. There is no clinically important difference in cosmesis (acceptable physical/cosmetic appearance) of dog bite wounds when primary closure is compared with no closure (mean difference (MD) ÃƒÂ¢Ã¢â€šÂ¬Ã‚Â1.31, 95% CI ÃƒÂ¢Ã¢â€šÂ¬Ã‚Â2.03 to ÃƒÂ¢Ã¢â€šÂ¬Ã‚Â0.59; 1 study, 182 participants). The certainty of evidence for this outcome was judged to be moderate (we downgraded our assessment by one level for imprecision). We are uncertain whether primary closure improves the proportion of dog bite wounds that are infectionÃƒÂ¢Ã¢â€šÂ¬Ã‚Âfree compared with delayed closure, as the evidence for this outcome was judged to be very low (RR 0.98, 95% CI 0.90 to 1.07; 1 study, 120 participants; I 2 = 0%). We downgraded the evidence by one level for high risk of bias and two levels for imprecision. None of the four trials reported any adverse outcomes such as death or rabies but they were, in any case, unlikely to have been large enough to have satisfactory power to provide precise estimates for these. Important outcomes like time to complete wound healing, proportion of wounds healed, and length of hospital stay were not evaluated. Authors' conclusions All the studies we identified concerned dog bites. There is no highÃƒÂ¢Ã¢â€šÂ¬Ã‚Âcertainty evidence to support or refute existing recommendations concerning primary closure for dog bites. The potential benefits and harms of primary closure compared with delayed or no closure for mammalian bites remain uncertain and more robust trials are needed. Plain language summary Primary closure (immediate stitches) versus delayed closure (delayed stitches) or no closure (no stitches) for traumatic wounds due to mammalian bite What is the aim of this review? The aim of this review was to find out whether animal bite wounds heal better when they are closed with stitches straight away (primary closure), or if th wounds are left open to heal for a short time before closure (delayed closure) or not stitched at all (no closure). We wanted to find out which wounds healed fastest, and if the method of closure affected the likelihood of wound infection, the appearance of the scar, the length of time patients were in hospital, and more serious side effects such as death. To answer this question, we collected and analysed all relevant studies (randomised controlled trials). Randomised controlled trials are medical studies where people are chosen at random to receive different treatments. This type of trial provides the most reliable health evidence. We found four relevant studies. Key messages All the studies we found concerned dog bites. In terms of wound infection, we cannot be certain whether it is better to close dog bite wounds straight away, or wait a while before stitching, or leave them with no stitches. There was little difference in the appearance of the bite scar. Most of the evidence we found was of low certainty due to the size of the studies and the methods used. What was studied in the review? Mammalian bite wounds from animals such as dogs, cats and monkeys are a common problem throughout the world. In developed countries, many bite wounds are caused by domestic pets. In lowerÃƒÂ¢Ã¢â€šÂ¬Ã‚Âincome countries bites can also be caused by wild animals. Dogs are generally responsible for the majority of bites. Bite wounds are at high risk of infection as microbes are transmitted into the wound from the animal's mouth. In lowerÃƒÂ¢Ã¢â€šÂ¬Ã‚Âincome countries these wound infections can lead to serious complications and in some cases death. The first priorities when treating an animal bite are to stop the flow of blood from the wound, provide pain relief, and prevent infection. This can include appropriate vaccination against tetanus and rabies. It is often recommended that bite wounds are not stitched straight away if infection is suspected, as closing an infected wound could delay healing and be potentially fatal. What are the main results of the review? In July 2019 we searched for randomised controlled trials comparing primary closure versus delayed or no closure for mammalian bite wounds. We found four relevant studies on dog bites. They were carried out in the UK, Greece and China. No other mammalian bite studies were identified. Three of the studies we included compared primary closure with sutures (immediate stitches) with no closure for dog bite wounds. One study compared primary closure with delayed closure for dog bites. The people in the studies were followed, where stated, from 14 days to three months. Overall, participants from both sexes and all age groups were represented. We are uncertain whether primary closure of dog bite wounds increases the proportion of wounds which are infectionÃƒÂ¢Ã¢â€šÂ¬Ã‚Âfree compared with no closure (very lowÃƒÂ¢Ã¢â€šÂ¬Ã‚Âcertainty evidence from two studies including a total of 782 people) and compared with delayed closure (very lowÃƒÂ¢Ã¢â€šÂ¬Ã‚Âcertainty evidence from one study with a total of 120 people). There is little difference in the appearance of dog bite wounds when primary closure is compared with no closure (moderateÃƒÂ¢Ã¢â€šÂ¬Ã‚Âcertainty evidence from one study with a total of 182 participants). None of the included studies reported proportion of wounds healed, the time to complete wound healing, length of hospital stay or adverse events. The number of people in the included studies was small, and the people who assessed the outcomes were aware of which treatment had been given. Both of these are reasons why the results are uncertain. How up to date is this review? We searched for studies that had been published up to July 2019. | E11: FALSE | F11: No primary cost or impact outcomes measured | G11: TRUE | H11: No intervention/Do nothing | I11: FALSE | J11: ['clinical'] | K11: 0.9
A12: J515 | B12: 2019 | C12: What evidence is available to support the development of a regional specialist neurorehabilitation outreach service | D12: Background The WHO recognises several specialist rehabilitation provision models; in-patient, outpatient and outreach. Intensive early neurorehabilitation is required after severe Acquired Brain Injury (ABI), usually necessitating in-patient care. In the UK, children receiving specialist neurorehabilitation often remain in-patients for long periods because of the lack of appropriate out-of-hospital provision. Aims To explore feasibility and funding implications of developing a regional specialist neurorehabilitation outreach service to facilitate earlier discharge. Methods Analysis of data on children receiving in-patient neurorehabilitation at a paediatric Regional Neuroscience Centre (RNSC), 2014-2018. Information concerning therapy provision was obtained from Trust Clinical Information System Suite (CISS). Patient dependency and rehabilitation complexity was assessed by Rehabilitation Complexity Scale-Extended (RCS-E), scored by multi-disciplinary team (MDT) at weekly meetings over 15 months. For modelling purposes, a specialist neurorehabilitation outreach tariff equating to 50% in-patient tariff was assumed. Data analysis was undertaken by linear programming model (XpressIveÃƒâ€šÃ‚Â©) and Discrete-Even Simulation (Simul8 Ãƒâ€šÃ‚Â©).Various eligibility criteria for outreach provision were modelled: 1) needing >=1 therapies<3 times/week; 2) Total RCS-E score <9,<11 or<13; 3) Therapy Dependency (TD) +Therapy Intensity (TI) components of RCS-E <5. Results 156 children received neurorehabilitation as in-patients over 4 years. Mean age=7.34 years (range 0.1-17). 66 (55%) were male, 53 (45%) female. 84% had ABI, others acquired spinal injury, acute polyneuropathy or somatisation disorders. 52% lived >40 miles from RNSC, 47%>60 min' drive away. 49% were inpatients 1-28 days; 34%, 29-84 days; 18, 85-168 days; 6,>168 days. Patients showed significant functional improvements between admission to neurorehabilitation and discharge (p<0.001). Modelling suggests 14 outreach centres, including RNSC, would be required to permit 78% patients to access specialist neurorehabilitation <30 mins drive from home; 10 centres would permit 92% to access neurorehabilitation <45 min' drive away; 8 centres would permit 96% to access neurorehabilitation <60 min' drive away. Calculations assuming outreach tariff=50% in-patient tariff, and various RCS data models, suggest annual cost savings ranging from 53,424-166,950; calculations based on CISS data, suggest average savings of 1 05 596 per year (range 98,500-113,526). Conclusion Modelling supports the feasibility and affordability of specialist neurorehabilitation outreach provision, although efficacy remains uncertain. | E12: FALSE | F12: No explicit comparator group mentioned | G12: FALSE | H12: Unknown | I12: TRUE | J12: ['cost', 'impact'] | K12: 0.8
A13: J520 | B13: 2019 | C13: The budget impact of early dose optimisation with golimumab in ulcerative colitis in the UK | D13: Background: The PURSUIT study found that ulcerative colitis patients who were non-responders (based on full Mayo score) to subcutaneous golimumab treatment at Week 6 may benefit from receiving a dose of 100 mg golimumab from Week 6 onwards, with 28% of non-responders at Week 6 becoming responders by Week 14. The aim of this study was to assess the budget implications of optimising a patient's dose at Week 6 compared with other first-line therapies as per current clinical practice Methods: A decision tree model was designed to follow a patient's response to first-line treatment and to track a patient's progression through subsequent line of therapy. The budget impact model only considered drug costs from the perspective of the UK NHS. In total three lines of therapy were covered by the decision tree over a 1 year time horizon. Patients could have first-line treatment with one of the three treatment strategies; golimumab (current treatment practice), golimumab (dose optimisation based on the PURSUIT trial) and adalimumab. Within each of the comparator treatments dose escalation was considered, based on the median time to escalation and proportion of patients receiving dose escalation. Subsequent therapy for golimumab patients was adalimumab and patients who received adalimumab as a first-line therapy received golimumab as a second-line therapy. Response rates, time to loss of response and treatment costs were taken from published data sources. The cost of golimumab was equal between 50 mg pack and 100 mg pack. The model used assumption for second-line response rates; this has been tested in sensitivity analysis. Result(s): The use of dose optimisation for golimumab does not increase expenditure of drug costs compared with golimumab (single dose) with a cost saving of 42 per patient per year. When comparing dose optimisation for golimumab to adalimumab, golimumab was cost saving over 1 year of treatment with cost saving of 2138 per patient. The number of patients in a response health state was similar across all three treatments (47.7%, 47.6% and 45% for golimumab (single dose), golimumab (dose optimisation) and adalimumab, respectively. Conclusion(s): The implementation of dose optimisation at Week 6 for golimumab was cost saving compared with golimumab (current treatment practice) or adalimumab. The analysis highlights the need for immediate implementation of the updated GLM label in clinical practice for potentially more cost savings. | E13: TRUE | F13: Uses comparator and measures cost outcomes. | G13: TRUE | H13: Other | I13: TRUE | J13: ['cost', 'impact'] | K13: 0.9
