Workbook

Sheet Stage_7_API_200
A1: id | B1: Year | C1: Title | D1: Abstract | E1: include_stage7 | F1: reason_stage7 | G1: cash_release_flags | H1: confidence_stage7
A2: J505 | B2: 2019 | C2: Fetal fibronectin testing for reducing the risk of preterm birth | D2: - Background Fetal fibronectin (FFN) is an extracellular matrix glycoprotein localized at the maternalÃƒÆ’Ã‚Â¢ÃƒÂ¢Ã¢â‚¬Å¡Ã‚Â¬Ãƒâ€šÃ‚Âfetal interface of the amniotic membranes, between chorion and decidua, where it is concentrated in this area between decidua and trophoblast. In normal conditions, FFN is found at very low levels in cervicovaginal secretions. Levels greater than or equal to 50 ng/mL at or after 22 weeks have been associated with an increased risk of spontaneous preterm birth. In fact, FFN is one of the best predictors of preterm birth in all populations studied so far, and can help in selecting which women are at significant risk for preterm birth. This is an update of a review first published in 2008. Objectives To assess the effectiveness of management based on knowledge of FFN testing results for preventing preterm birth. Search methods For this update, we searched Cochrane Pregnancy and ChildbirthÃƒÆ’Ã‚Â¢ÃƒÂ¢Ã¢â‚¬Å¡Ã‚Â¬ÃƒÂ¢Ã¢â‚¬Å¾Ã‚Â¢s Trials Register (7 September 2018), ClinicalTrials.gov , the WHO International Clinical Trials Registry Platform ( ICTRP ) (7 September 2018), and reference lists of retrieved studies. Selection criteria Randomized controlled trials of pregnant women screened with FFN for risk of preterm birth. Studies included are based exclusively on knowledge of FFN results versus no such knowledge, and we have excluded studies including women with only positive or only negative FFN results. Data collection and analysis Two review authors independently assessed trials for inclusion and risk of bias, extracted data, and checked them for accuracy. The quality of the evidence was assessed using the GRADE approach. Main results We identified 16 trials, of which six were eligible for inclusion. The six included studies randomized 546 women with singleton gestations and threatened preterm labor (PTL) at 23 0/7 to 34 6/7 weeks. A total of 277 women were randomized to knowledge and 269 to no knowledge of FFN. No trials were identified on asymptomatic women or multiple gestations. The risk of bias of included studies was mixed. For selected important outcomes, preterm birth before 37, 34, and 32 weeks, and maternal hospitalization, we graded the quality of the evidence and created a 'Summary of findings' table. For these outcomes, the evidence was graded as mainly low quality due to the imprecision of effect estimates. Management based on knowledge of FFN results may reduce preterm birth before 37 weeks (20.7%) versus controls without such knowledge (29.2%) (risk ratio (RR) 0.72, 95% confidence interval (CI) 0.52 to 1.01; 5 trials; 434 women; lowÃƒÆ’Ã‚Â¢ÃƒÂ¢Ã¢â‚¬Å¡Ã‚Â¬Ãƒâ€šÃ‚Âquality evidence). However, management based on knowledge of FFN results may make little or no difference to preterm birth before 34 (RR 1.09, 95% CI 0.54 to 2.18; 4 trials; 357 women; lowÃƒÆ’Ã‚Â¢ÃƒÂ¢Ã¢â‚¬Å¡Ã‚Â¬Ãƒâ€šÃ‚Âquality evidence) or maternal hospitalization (RR 1.06, 95% CI 0.79 to 1.43; 5 trials; 441 women; lowÃƒÆ’Ã‚Â¢ÃƒÂ¢Ã¢â‚¬Å¡Ã‚Â¬Ãƒâ€šÃ‚Âquality evidence). The evidence for preterm birth before 32 weeks is uncertain because the quality was found to be very low (average RR 0.79, 95% CI 0.16 to 3.96; 4 trials; 357 women; very lowÃƒÆ’Ã‚Â¢ÃƒÂ¢Ã¢â‚¬Å¡Ã‚Â¬Ãƒâ€šÃ‚Âquality evidence). For all other outcomes, for which there were available data (preterm birth less than 28 weeks; gestational age at delivery (weeks); birthweight less than 2500 g; perinatal death; tocolysis; steroids for fetal lung maturity; time to evaluate; respiratory distress syndrome; neonatal intensive care unit (NICU) admission; and NICU days), knowledge of FFN results may make little or no difference to the outcomes. Authors' conclusions The evidence from this review suggests that management based on knowledge of FFN results may reduce preterm birth before 37 weeks. However, our confidence in this result is limited as the evidence was found to be of low quality. Effects on other substantive outcomes are uncertain due to serious concerns in study design, inconsistency, and imprecision of effect estimates. No trials were identified on asymptomatic women, or multiple gestations. Future studies are needed that include specific populations (e.g. singleton gestations with symptoms of preterm labor), a study gro p managed with a protocol based on the FFN results, and that report not only maternal but also important perinatal outcomes. CostÃƒÆ’Ã‚Â¢ÃƒÂ¢Ã¢â‚¬Å¡Ã‚Â¬Ãƒâ€šÃ‚Âeffectiveness analyses are also needed. Plain language summary Fetal fibronectin testing for reducing the risk of preterm birth What is the issue? To assess the effectiveness of management of pregnant women based on a knowledge of fetal fibronectin test results for preventing preterm birth, compared with not having that knowledge. Fetal fibronectin (FFN) acts as a ÃƒÆ’Ã‚Â¢ÃƒÂ¢Ã¢â‚¬Å¡Ã‚Â¬Ãƒâ€¹Ã…â€œglueÃƒÆ’Ã‚Â¢ÃƒÂ¢Ã¢â‚¬Å¡Ã‚Â¬ÃƒÂ¢Ã¢â‚¬Å¾Ã‚Â¢ between the pregnancy and the uterus. Normally very low levels of FFN can be found in secretions of the vagina and cervix. Raised levels at or after 22 weeks have been associated with an increased risk of spontaneous preterm birth. Why is this important? Preterm birth before 37 weeks is the main cause of sickness and death for newborn infants. Most women who give birth preterm have preterm labor symptoms such as contractions but many of the women with symptoms go on to deliver at term (37 weeks or more). Fetal fibronectin (FFN) is a test that can identify the women with symptoms of preterm labor who are most at risk for preterm birth. The level of FFN is measured in secretions from the vagina or cervix. What evidence did we find? We found six randomised controlled studies involving 546 women who were pregnant with one baby and were showing signs of preterm labor at between 23 to 34 weeks' gestation. We graded the following evidence as mainly low quality because of the low number of women in the studies and a wide variation in findings. We found that the number of births before 37 weeks may be slightly reduced when women and their doctors know the results of the FFN test (20.7% versus 29.2%; 5 trials; 434 women). However, knowledge of FFN results may make little or no difference for the other outcomes with available data, including: maternal hospitalization (5 trials; 441 women); use of uterine relaxants (tocolysis) to try to prevent labor; earlier preterm births; womenÃƒÆ’Ã‚Â¢ÃƒÂ¢Ã¢â‚¬Å¡Ã‚Â¬ÃƒÂ¢Ã¢â‚¬Å¾Ã‚Â¢s gestational age at delivery; babies with a birthweight less than 2500 g; newborn deaths; the number of babies with respiratory distress syndrome; giving steroids to mature the unborn babiesÃƒÆ’Ã‚Â¢ÃƒÂ¢Ã¢â‚¬Å¡Ã‚Â¬ÃƒÂ¢Ã¢â‚¬Å¾Ã‚Â¢ lungs; and number of days in a neonatal intensive care unit (NICU). What does this mean? This review of six studies did not find enough evidence to say whether or not the FFN test should be used in the management of women showing signs of preterm labor. A screening test such as FFN can only be considered effective if interventions based on the screening results, such as giving drugs to relax the uterus, reduce the number of preterm births. Further research should be encouraged. | E2: FALSE | F2: No explicit budget reduction or cash-releasing benefits mentioned. | G2: no_cost_shift_or_harm | H2: 0.9
A3: J535 | B3: 2019 | C3: Interventions for prodromal stage of psychosis | D3: - Background Psychosis is a serious mental condition characterised by a loss of contact with reality. There may be a prodromal period or stage of psychosis, where early signs of symptoms indicating onset of first episode psychosis (FEP) occur. A number of services, incorporating multimodal treatment approaches (pharmacotherapy, psychotherapy and psychosocial interventions), developed worldwide, now focus on this prodromal period with the aim of preventing psychosis in people at risk of developing FEP. Objectives The primary objective is to assess the safety and efficacy of early interventions for people in the prodromal stage of psychosis. The secondary objective is, if possible, to compare the effectiveness of the various different interventions. Search methods We searched Cochrane Schizophrenia's studyÃƒÆ’Ã‚Â¢ÃƒÂ¢Ã¢â‚¬Å¡Ã‚Â¬Ãƒâ€šÃ‚Âbased Register of studies (including trials registers) on 8 June 2016 and 4 August 2017. Selection criteria All randomised controlled trials (RCTs) evaluating interventions for participants older than 12 years, who had developed a prodromal stage of psychosis. Data collection and analysis Review authors independently inspected citations, selected studies, extracted data, and assessed study quality. Main results We included 20 studies with 2151 participants. The studies analysed 13 different comparisons. Group A comparisons explored the absolute effects of the experimental intervention. Group B were comparisons within which we could not be clear whether differential interactive effects were also ongoing. Group C comparisons explored differential effects between clearly distinct treatments. A key outcome for this review was ÃƒÆ’Ã‚Â¢ÃƒÂ¢Ã¢â‚¬Å¡Ã‚Â¬Ãƒâ€¹Ã…â€œtransition to psychosisÃƒÆ’Ã‚Â¢ÃƒÂ¢Ã¢â‚¬Å¡Ã‚Â¬ÃƒÂ¢Ã¢â‚¬Å¾Ã‚Â¢. For details of other main outcomes please see 'Summary of findings' tables. In Group A (comparisons of absolute effects) we found no clear difference between amino acids and placebo (risk ratio (RR) 0.48 95% confidence interval (CI) 0.08 to 2.98; 2 RCTs, 52 participants; very lowÃƒÆ’Ã‚Â¢ÃƒÂ¢Ã¢â‚¬Å¡Ã‚Â¬Ãƒâ€šÃ‚Âquality evidence). When omegaÃƒÆ’Ã‚Â¢ÃƒÂ¢Ã¢â‚¬Å¡Ã‚Â¬Ãƒâ€šÃ‚Â3 fatty acids were compared to placebo, fewer participants given the omegaÃƒÆ’Ã‚Â¢ÃƒÂ¢Ã¢â‚¬Å¡Ã‚Â¬Ãƒâ€šÃ‚Â3 (10%) transitioned to psychosis compared to the placebo group (33%) during longÃƒÆ’Ã‚Â¢ÃƒÂ¢Ã¢â‚¬Å¡Ã‚Â¬Ãƒâ€šÃ‚Âterm followÃƒÆ’Ã‚Â¢ÃƒÂ¢Ã¢â‚¬Å¡Ã‚Â¬Ãƒâ€šÃ‚Âup of seven years (RR 0.24 95% CI 0.09 to 0.67; 1 RCT, 81 participants; lowÃƒÆ’Ã‚Â¢ÃƒÂ¢Ã¢â‚¬Å¡Ã‚Â¬Ãƒâ€šÃ‚Âquality evidence). In Group B (comparisons where complex interactions are probable) and in the subgroup focusing on antipsychotic drugs added to specific care packages, the amisulpiride + needsÃƒÆ’Ã‚Â¢ÃƒÂ¢Ã¢â‚¬Å¡Ã‚Â¬Ãƒâ€šÃ‚Âfocused intervention (NFI) compared to NFI comparison (no reporting of transition to psychosis; 1 RCT, 102 participants; very lowÃƒÆ’Ã‚Â¢ÃƒÂ¢Ã¢â‚¬Å¡Ã‚Â¬Ãƒâ€šÃ‚Âquality evidence) and the olanzapine + supportive intervention compared to supportive intervention alone comparison (RR 0.58 95% CI 0.28 to 1.18; 1 RCT, 60 participants; very lowÃƒÆ’Ã‚Â¢ÃƒÂ¢Ã¢â‚¬Å¡Ã‚Â¬Ãƒâ€šÃ‚Âquality evidence) showed no clear differences between groups. In the second Group B subgroup (cognitive behavioural therapies (CBT)), when CBT + supportive therapy was compared with supportive therapy alone around 8% of participants allocated to the combination of CBT and supportive therapy group transitioned to psychosis during followÃƒÆ’Ã‚Â¢ÃƒÂ¢Ã¢â‚¬Å¡Ã‚Â¬Ãƒâ€šÃ‚Âup by 18 months, compared with double that percentage in the supportive therapy alone group (RR 0.45 95% CI 0.23 to 0.89; 2 RCTs, 252 participants; very lowÃƒÆ’Ã‚Â¢ÃƒÂ¢Ã¢â‚¬Å¡Ã‚Â¬Ãƒâ€šÃ‚Âquality evidence). The CBT + risperidone versus CBT + placebo comparison identified no clear difference between treatments (RR 1.02 95% CI 0.39 to 2.67; 1 RCT, 87 participants; very lowÃƒÆ’Ã‚Â¢ÃƒÂ¢Ã¢â‚¬Å¡Ã‚Â¬Ãƒâ€šÃ‚Âquality evidence) and this also applies to the CBT + needsÃƒÆ’Ã‚Â¢ÃƒÂ¢Ã¢â‚¬Å¡Ã‚Â¬Ãƒâ€šÃ‚Âbased intervention (NBI) + risperidone versus NBI comparison (RR 0.75 95% CI 0.39 to 1.46; 1 RCT, 59 participants; very lowÃƒÆ’Ã‚Â¢ÃƒÂ¢Ã¢â‚¬Å¡Ã‚Â¬Ãƒâ€šÃ‚Âquality evidence). Group C (differential effects) also involved six comparisons. The first compared CBT with supportive therapy. No clear difference was found for the ÃƒÆ’Ã‚Â¢ÃƒÂ¢Ã¢â‚¬Å¡Ã‚Â¬Ãƒâ€¹Ã…â€œtransition to psychosisÃƒÆ’Ã‚Â¢ÃƒÂ¢Ã¢â‚¬Å¡Ã‚Â¬ÃƒÂ¢Ã¢â‚¬Å¾Ã‚Â¢ outcome (RR 0.74 95% CI 0.28 to 1.98; 1 RCT, 72 participants; very lowÃƒÆ’Ã‚Â¢ÃƒÂ¢Ã¢â‚¬Å¡Ã‚Â¬Ãƒâ€šÃ‚Âquality evidence). The second subgroup compared CBT + supportive intervention was compared with a NBI + supportive intervention, again, data were equivocal, few and of very low quality (RR 6.32 95% CI 0.34 to 117.09; 1 RCT, 57 participants). In the CBT + risperidone versus supportive therapy comparison, again there was no clear difference between groups (RR 0.76 95% CI 0.28 to 2.03; 1 RCT, 71 participants; very lowÃƒÆ’Ã‚Â¢ÃƒÂ¢Ã¢â‚¬Å¡Ã‚Â¬Ãƒâ€šÃ‚Âquality evidence). The three other comparisons in Group C demonstrated no clear differences between treatment groups. When cognitive training was compared to active control (tablet games) (no reporting of transition to psychosis; 1 RCT, 62 participants; very low quality data), family treatment compared with enhanced care comparison (RR 0.54 95% CI 0.18 to 1.59; 2 RCTs, 229 participants; very lowÃƒÆ’Ã‚Â¢ÃƒÂ¢Ã¢â‚¬Å¡Ã‚Â¬Ãƒâ€šÃ‚Âquality evidence) and integrated treatment compared to standard treatment comparison (RR 0.57 95% CI 0.28 to 1.15; 1 RCT, 79 participants; very lowÃƒÆ’Ã‚Â¢ÃƒÂ¢Ã¢â‚¬Å¡Ã‚Â¬Ãƒâ€šÃ‚Âquality evidence) no effects of any of these approaches was evident. Authors' conclusions There has been considerable research effort in this area and several interventions have been trialled. The evidence available suggests that omegaÃƒÆ’Ã‚Â¢ÃƒÂ¢Ã¢â‚¬Å¡Ã‚Â¬Ãƒâ€šÃ‚Â3 fatty acids may prevent transition to psychosis but this evidence is low quality and more research is needed to confirm this finding. Other comparisons did not show any clear differences in effect for preventing transition to psychosis but again, the quality of this evidence is very low or low and not strong enough to make firm conclusions. Plain language summary Early interventions for people at risk of developing psychosis Review question Is there highÃƒÆ’Ã‚Â¢ÃƒÂ¢Ã¢â‚¬Å¡Ã‚Â¬Ãƒâ€šÃ‚Âquality evidence indicating that interventions for people at risk of developing psychosis are effective? Background Psychoses are serious mental conditions characterised by a loss of contact with reality. The first clear episode of psychosis can be preceded by a 'prodromal' period of at least six months, where a person experiences gradual nonÃƒÆ’Ã‚Â¢ÃƒÂ¢Ã¢â‚¬Å¡Ã‚Â¬Ãƒâ€šÃ‚Âspecific changes in thoughts, perceptions, behaviours and functioning. Although an individual is experiencing changes, they have not yet started to experience the more obvious psychotic symptoms such as delusions (fixed false beliefs) or hallucinations (perceptions without a cause). A number of services with treatment approaches that combine pharmacotherapy, psychotherapy and psychosocial treatments, developed worldwide, are now focusing on prevention of psychosis in people at risk by giving treatments during this prodromal period. This review assesses the evidence available concerning the effects of different treatment approaches for people not yet diagnosed with a non affective psychosis but who are in the prodromal stage of psychosis. Searching for evidence On 8 June 2016 and 4 August 2017 we ran electronic searches of the Cochrane Schizophrenia's specialised register of studies in order to find clinical studies that randomly allocated individuals at risk of developing psychosis to receive various treatments for preventing development of psychosis. Evidence found We were able to include 20 studies with 2151 participants. These studies analysed a wide range of treatments. All the review findings are of, at very best, low quality. There is some suggestion from one small study that people at risk of psychosis may benefit from taking omegaÃƒÆ’Ã‚Â¢ÃƒÂ¢Ã¢â‚¬Å¡Ã‚Â¬Ãƒâ€šÃ‚Â3 fatty acids in terms of reduced transition to psychosis. Other studies found adding antipsychotic drugs to supportiveÃƒÆ’Ã‚Â¢ÃƒÂ¢Ã¢â‚¬Å¡Ã‚Â¬Ãƒâ€šÃ‚Âcare packages did not seem to make much difference in terms of transition to full illness. When cognitive behavioural therapy (CBT) + supportive therapy was compared with supportive therapy alone around 8% of participants treated allocated to the combination of CBT and supportive therapy transitioned to psychosis during followÃƒÆ’Ã‚Â¢ÃƒÂ¢Ã¢â‚¬Å¡Ã‚Â¬Ãƒâ€šÃ‚Âup by 18 months, compared with double that percentage in people who just received supportive therapy. This could be important but these data are of very low quality. All other testing of CBT and other packages of care found no clear difference between treatments for transition to psychosis. Conclusions There has been considerable effort and expense invested testing treatment approaches for prevention of the first episode of schizophr nia. Currently, there is some lowÃƒÆ’Ã‚Â¢ÃƒÂ¢Ã¢â‚¬Å¡Ã‚Â¬Ãƒâ€šÃ‚Âquality evidence suggesting that omegaÃƒÆ’Ã‚Â¢ÃƒÂ¢Ã¢â‚¬Å¡Ã‚Â¬Ãƒâ€šÃ‚Â3 fatty acids may be effective, but there is no highÃƒÆ’Ã‚Â¢ÃƒÂ¢Ã¢â‚¬Å¡Ã‚Â¬Ãƒâ€šÃ‚Âquality evidence to suggest that any type of treatment is effective, and no firm conclusions can be made. | E3: FALSE | F3: Focus on efficacy and safety, not budget or cost reduction. | H3: 0.9
A4: J545 | B4: 2019 | C4: Estimating the cost-effectiveness of salt reformulation and increasing access to leisure centres in England, with PRIMEtime CE model validation using the AdViSHE tool | D4: BACKGROUND: PRIMEtime CE is a multistate life table model that can directly compare the cost effectiveness of public health interventions affecting diet and physical activity levels, helping to inform decisions about how to spend finite resources. This paper estimates the costs and health outcomes in England of two scenarios: reformulating salt and expanding subsidised access to leisure centres. The results are used to help validate PRIMEtime CE, following the steps outlined in the Assessment of the Validation Status of Health-Economic decision models (AdViSHE) tool. METHOD(S): The PRIMEtime CE model estimates the difference in quality adjusted life years (QALYs) and difference in NHS and social care costs of modelled interventions compared with doing nothing. The salt reformulation scenario models how salt consumption would change if food producers met the 2017 UK Food Standards Agency salt reformulation targets. The leisure centre scenario models change in physical activity levels if the Birmingham Be Active scheme (where swimming pools and gym access is free to residents during defined periods) was rolled out across England. The AdViSHE tool was developed by health economic modellers and divides model validation into five parts: validation of the conceptual model, input data validation, validation of computerised model, operational validation, and other validation techniques. PRIMEtime CE is discussed in relation to each part. RESULT(S): Salt reformulation was dominant compared with doing nothing, and had a 10-year return on investment of 1.44 (0.50 to 2.94) for every 1 spent. By contrast, over 10 years the Be Active expansion would cost 727,000 (514,000 to 1,064,000) per QALY. PRIMEtime CE has good face validity of its conceptual model and has robust input data. Cross-validation produces mixed results and shows the impact of model scope, input parameters, and model structure on cost-per-QALY estimates. CONCLUSION(S): This paper illustrates how PRIMEtime CE can be used to compare the cost-effectiveness of two different public health measures affecting diet and physical activity levels. The AdViSHE tool helps to validate PRIMEtime CE, identifies some of the key drivers of model estimates, and highlights the challenges of externally validating public health economic models against independent data. | E4: FALSE | F4: Focuses on cost-effectiveness, not explicit budget reduction. | G4: has_baseline_and_counterfactual; no_cost_shift_or_harm | H4: 0.9
A5: J547 | B5: 2019 | C5: Individualised screening for diabetic retinopathy: The ISDR study-a randomised controlled trial of safety, efficacy, and cost-effectiveness | D5: Background: Varying the intervals in retinopathy screening informed by personal risk offers reallocation of resources to better target high risk groups and address the increasing prevalence of diabetes. However, safety data especially on extended intervals is minimal. Aim(s): To evaluate the safety, efficacy and cost effectiveness (CE) of individualized variable-interval risk-based screening in a population setting compared to usual care. Method(s): Masked 2 arm, parallel assignment, equivalence RCT (largest to date in screening) with independent trials unit monitoring in people with diabetes aged >=12 years attending screening in a single English program. Randomization was 1:1 to individualized screening (active group; 6, 12 or 24 months for high, medium and low risk) determined by a risk calculation engine using real-time local demographic, retinal and clinical data, compared with annual screening (control). CE analysis measuring NHS and societal costs took a 2-year time horizon. Finding(s): 4534 participants entered the study-after withdrawals/loss to follow-up: active 2097; control 2224. Attendance rates at first follow-up visit (primary outcome, safety) were equivalent (per protocol analysis, 5% margin): active 83.6% control 84.7% (difference 1.0, 90% CI-0.8, 2.9). STDR detection rates were non-inferior (1.5% margin): active 1.43% control 1.71% (difference-0.28, CI-0.93, 0.36). Quality of life (EQ5D5L, HUI3) was not significantly different between the groups. Incremental cost saving per person was 18.75 (NHS cost) rising to 49.96 with societal costs. A 39.3% reduction in number of appointments was seen. Conclusion(s): All parties involved in diabetes care can be reassured that extended and personalized screening intervals can safely be introduced in established screening program. Scale-up with further validation outside a research setting is recommended. Views expressed are solely those of the authors. | E5: FALSE | F5: Mentions cost savings but lacks explicit budget reduction or cash-releasing mechanism. | G5: no_cost_shift_or_harm | H5: 0.7
A6: J552 | B6: 2019 | C6: PharmacyÃƒÆ’Ã‚Â¢ÃƒÂ¢Ã¢â‚¬Å¡Ã‚Â¬Ãƒâ€šÃ‚Âbased management for depression in adults | D6: - Background It is common for people not to take antidepressant medication as prescribed, with around 50% of people likely to prematurely discontinue taking their medication after six months. Community pharmacists may be well placed to have a role in antidepressant management because of their unique pharmacotherapeutic knowledge and ease of access for people. Pharmacists are in an ideal position to offer proactive interventions to people with depression or depressive symptoms. However, the effectiveness and acceptability of existing pharmacistÃƒÆ’Ã‚Â¢ÃƒÂ¢Ã¢â‚¬Å¡Ã‚Â¬Ãƒâ€šÃ‚Âbased interventions is not yet well understood. The degree to which a pharmacyÃƒÆ’Ã‚Â¢ÃƒÂ¢Ã¢â‚¬Å¡Ã‚Â¬Ãƒâ€šÃ‚Âbased management approach might be beneficial, acceptable to people, and effective as part of the overall management for those with depression is, to date, unclear. A systematic review of randomised controlled trials (RCTs) will help answer these questions and add important knowledge to the currently sparse evidence base. Objectives To examine the effects of pharmacyÃƒÆ’Ã‚Â¢ÃƒÂ¢Ã¢â‚¬Å¡Ã‚Â¬Ãƒâ€šÃ‚Âbased management interventions compared with active control (e.g. patient information materials or any other active intervention delivered by someone other than the pharmacist or the pharmacy team), waiting list, or treatment as usual (e.g. standard pharmacist advice or antidepressant education, signposting to support available in primary care services, brief medication counselling, and/or (selfÃƒÆ’Ã‚Â¢ÃƒÂ¢Ã¢â‚¬Å¡Ã‚Â¬Ãƒâ€šÃ‚Â)monitoring of medication adherence offered by a healthcare professional outside the pharmacy team) at improving depression outcomes in adults. Search methods We searched the Cochrane Common Mental Disorders Controlled Trials Register (CCMDÃƒÆ’Ã‚Â¢ÃƒÂ¢Ã¢â‚¬Å¡Ã‚Â¬Ãƒâ€šÃ‚ÂCTR) to June 2016; the Cochrane Library (Issue 11, 2018); and Ovid MEDLINE, Embase, and PsycINFO to December 2018. We searched theses and dissertation databases and international trial registers for unpublished/ongoing trials. We applied no restrictions on date, language, or publication status to the searches. Selection criteria We included all RCTs and clusterÃƒÆ’Ã‚Â¢ÃƒÂ¢Ã¢â‚¬Å¡Ã‚Â¬Ãƒâ€šÃ‚ÂRCTs where a pharmacyÃƒÆ’Ã‚Â¢ÃƒÂ¢Ã¢â‚¬Å¡Ã‚Â¬Ãƒâ€šÃ‚Âbased intervention was compared with treatment as usual, waiting list, or an alternative intervention in the management of depression in adults over 16 years of age. Eligible studies had to report at least one of the following outcomes at any time point: depression symptom change, acceptability of the intervention, diagnosis of depression, nonÃƒÆ’Ã‚Â¢ÃƒÂ¢Ã¢â‚¬Å¡Ã‚Â¬Ãƒâ€šÃ‚Âadherence to medication, frequency of primary care appointments, quality of life, social functioning, or adverse events. Data collection and analysis Two authors independently, and in duplicate, conducted all stages of study selection, data extraction, and quality assessment (including GRADE). We discussed disagreements within the team until we reached consensus. Where data did not allow metaÃƒÆ’Ã‚Â¢ÃƒÂ¢Ã¢â‚¬Å¡Ã‚Â¬Ãƒâ€šÃ‚Âanalyses, we synthesised results narratively. Main results Twelve studies (2215 participants) met the inclusion criteria and compared pharmacyÃƒÆ’Ã‚Â¢ÃƒÂ¢Ã¢â‚¬Å¡Ã‚Â¬Ãƒâ€šÃ‚Âbased management with treatment as usual. Two studies (291 participants) also included an active control (both used patient information leaflets providing information about the prescribed antidepressant). Neither of these studies reported depression symptom change. A narrative synthesis of results on acceptability of the intervention was inconclusive, with one study reporting better acceptability of pharmacyÃƒÆ’Ã‚Â¢ÃƒÂ¢Ã¢â‚¬Å¡Ã‚Â¬Ãƒâ€šÃ‚Âbased management and the other better acceptability of the active control. One study reported that participants in the pharmacyÃƒÆ’Ã‚Â¢ÃƒÂ¢Ã¢â‚¬Å¡Ã‚Â¬Ãƒâ€šÃ‚Âbased management group had better medication adherence than the control participants. One study reported adverse events with no difference between groups. The studies reported no other outcomes. MetaÃƒÆ’Ã‚Â¢ÃƒÂ¢Ã¢â‚¬Å¡Ã‚Â¬Ãƒâ€šÃ‚Âanalyses comparing pharmacyÃƒÆ’Ã‚Â¢ÃƒÂ¢Ã¢â‚¬Å¡Ã‚Â¬Ãƒâ€šÃ‚Âbased management with treatment as usual showed no evidence of a difference in the effect of the intervention on depression symptom change (dichotomous data; improvement in symptoms yes/no: risk ratio (RR), 0.95, 95% confidence interval (CI) 0.86 to 1.05; 4 RCTs, 475 participants; moderateÃƒÆ’Ã‚Â¢ÃƒÂ¢Ã¢â‚¬Å¡Ã‚Â¬Ãƒâ€šÃ‚Âquality evidence; continuous data: standard mean difference (SMD) ÃƒÆ’Ã‚Â¢ÃƒÂ¢Ã¢â‚¬Å¡Ã‚Â¬Ãƒâ€šÃ‚Â0.04, 95% | E6: FALSE | F6: No explicit budget reduction or cash-releasing benefits mentioned. | G6: no_cost_shift_or_harm | H6: 0.9
A7: J571 | B7: 2019 | C7: Alternative community-based models of care for young people with anorexia nervosa: the CostED national surveillance study | D7: <b>BACKGROUND</b>: Evidence suggests that investing in specialist eating disorders services for young people with anorexia nervosa could have important implications for the NHS, with the potential to improve health outcomes and reduce costs through reductions in the number and length of hospital admissions._x000D_ <b>OBJECTIVES</b>: The primary objectives were to evaluate the costs and cost-effectiveness of alternative community-based models of service provision for young people with anorexia nervosa and to model the impact of potential changes to the provision of specialist services._x000D_ <b>DESIGN</b>: Observational surveillance study using the Child and Adolescent Psychiatry Surveillance System._x000D_ <b>SETTING</b>: Community-based secondary or tertiary child and adolescent mental health services (CAMHS) in the UK and the Republic of Ireland._x000D_ <b>PARTICIPANTS</b>: A total of 298 young people aged 8-17 years in contact with CAMHS for a first episode of anorexia nervosa in accordance with Diagnostic and Statistical Manual of Mental Disorders, Fifth Edition, diagnostic criteria._x000D_ <b>INTERVENTIONS</b>: Community-based specialist eating disorders services and generic CAMHS._x000D_ <b>MAIN OUTCOME MEASURES</b>: Children's Global Assessment Scale (CGAS) score (primary outcome) and percentage of median expected body mass index (BMI) for age and sex (%mBMI) (secondary outcome) were assessed at baseline and at 6 and 12 months._x000D_ <b>DATA SOURCES</b>: Data were collected by clinicians from clinical records._x000D_ <b>RESULTS</b>: Total costs incurred by young people initially assessed in specialist eating disorders services were not significantly different from those incurred by young people initially assessed in generic CAMHS. However, adjustment for baseline covariates resulted in observed differences favouring specialist services (costs were lower, on average) because of the significantly poorer clinical status of the specialist group at baseline. At the 6-month follow-up, mean %mBMI was significantly higher in the specialist group, but no other significant differences in outcomes were evident. Cost-effectiveness analyses suggest that initial assessment in a specialist service has a higher probability of being cost-effective than initial assessment in generic CAMHS, as determined by CGAS score and %mBMI. However, no firm conclusion can be drawn without knowledge of society's willingness to pay for improvements in these outcomes. Decision modelling did not support the hypothesis that changes to the provision of specialist services would generate savings for the NHS, with results suggesting that cost per 10-point improvement in CGAS score (improvement from one CGAS category to the next) varies little as the percentage of participants taking the specialist or generic pathway is varied._x000D_ <b>LIMITATIONS</b>: Follow-up rates were lower than expected, but the sample was still larger than has been achieved to date in RCTs carried out in this population in the UK, and an exploration of the impact of missing cost and outcome data produced very similar results to those of the main analyses._x000D_ <b>CONCLUSIONS</b>: The results of this study suggest that initial assessment in a specialist eating disorders service for young people with anorexia nervosa may have a higher probability of being cost-effective than initial assessment in generic CAMHS, although the associated uncertainty makes it hard to draw firm conclusions. Although costs and outcomes were similar, young people in specialist services were more severely ill at baseline, suggesting that specialist services were achieving larger clinical effectiveness gains without the need for additional expenditure. The results did not suggest that providing more specialist services would save money for the NHS, given similar costs and outcomes, so decisions about which service type to fund could be made with reference to other factors, such as the preferences of patients and carers._x000D_ <b>FUTURE WORK</b>: Data on measures of quality of life capable of generating quality-adjusted life-years are needed to confirm the cost-effectiveness of specialist services._x000D_ <b>TRIAL REGISTRATION</b>: Current Controlled Trials ISRCTN12676087._x000D_ <b>FUNDING</b>: This project was funded by the National Institute for Health Research (NIHR) Health Services and Delivery Research programme and will be published in full in Health Services and Delivery Research; Vol. 7, No. 37. See the NIHR Journals Library website for further project information. | E7: FALSE | F7: Study shows no cost savings; similar costs and outcomes. | G7: has_baseline_and_counterfactual; no_cost_shift_or_harm | H7: 0.9
A8: J574 | B8: 2019 | C8: Abstract 2415: Polygenic risk-tailored screening for prostate cancer: A costeffectiveness Analysis | D8: Background Screening for prostate cancer with prostate specific antigen (PSA) remains controversial. Risk-tailoring based on age and polygenic profile might conserve the benefits of PSA screening whilst reducing overdiagnosis. This study evaluates the cost-effectiveness and benefit-to-harm balance of polygenic risk-tailored screening for prostate cancer. Methods A life-table approach was used. A hypothetical cohort of 4.48 million men in England between the ages of 55 and 70 was followed to the age of 90. Three scenarios were compared: No screening, age-based screening (PSA testing every four years from 55 to 70), and risk-tailored screening based on age and polygenic risk profile (men above the risk threshold receive PSA testing four-yearly from the age they reach the risk threshold to 70). The number of prostate cancer cases, deaths from prostate cancer, overdiagnosed cases, life-years and quality-adjusted life-years (QALYs), incremental cost per QALY, and net monetary benefit were calculated. Sensitivity analyses investigated the impact of parameter uncertainty, and the impact of varying the risk threshold, on outcomes. Costs were estimated from the perspective of the UK National Health Service; both costs and benefits were discounted at 3.5%. Results The incremental cost per additional QALY for age-based screening compared to no screening was 58,254 ($75,899), with 27% simulations having an incremental cost-effectiveness ratio of less than 20,000 ($26,058), the threshold set by the UK National Institute for Health and Care Excellence for an intervention to be considered costeffective. In risk-tailored screening, as the 10-year absolute risk-threshold was progressively increased from 2.6%, equivalent to the 10-year absolute risk of a 55-year old man, to 7.1%, the corresponding risk of a 69-year old man, the cost per additional QALY gained reduced from 36,065 ($46,989) to 26,210 ($34,149), when compared to no screening. By comparison with age-based screening, risk-tailored screening with a threshold between 2.6% and 7.1% led to 8 (2.5%) and 45 (13%) fewer deaths prevented from prostate cancer per 10,000 men, with a 0.1% rise and 10% reduction in costs, respectively. Raising the risk threshold from 2.6% to 7.1% led to fewer men being screened (cumulative total of 35% of men screened by comparison with 83%), 53% fewer overdiagnosed cases, 22% fewer biopsies and 10% lower costs, at the expense of 10% fewer prostate cancer deaths averted. Conclusion Risk-tailored screening reduces the harms of screening for prostate cancer whilst preserving much of the mortality benefit. This study raises the prospect of risktailored population-based screening for prostate cancer; the precise risk-thresholds selected will depend on societal judgements regarding the appropriate trade-offs between harms and benefits. | E8: FALSE | F8: Focuses on cost-effectiveness, not explicit budget reduction or cash-releasing benefits. | G8: has_baseline_and_counterfactual | H8: 0.8
A9: J575 | B9: 2019 | C9: Polygenic risk-tailored screening for prostate cancer: A benefit-harm and cost-effectiveness modelling study | D9: Background The United States Preventive Services Task Force supports individualised decision-making for prostate-specific antigen (PSA)-based screening in men aged 55-69. Knowing how the potential benefits and harms of screening vary by an individual's risk of developing prostate cancer could inform decision-making about screening at both an individual and population level. This modelling study examined the benefit-harm tradeoffs and the cost-effectiveness of a risk-tailored screening programme compared to age-based and no screening. Methods and findings A life-table model, projecting age-specific prostate cancer incidence and mortality, was developed of a hypothetical cohort of 4.48 million men in England aged 55 to 69 years with follow-up to age 90. Risk thresholds were based on age and polygenic profile. We compared no screening, age-based screening (quadrennial PSA testing from 55 to 69), and risk-tailored screening (men aged 55 to 69 years with a 10-year absolute risk greater than a threshold receive quadrennial PSA testing from the age they reach the risk threshold). The analysis was undertaken from the health service perspective, including direct costs borne by the health system for risk assessment, screening, diagnosis, and treatment. We used probabilistic sensitivity analyses to account for parameter uncertainty and discounted future costs and benefits at 3.5% per year. Our analysis should be considered cautiously in light of limitations related to our model's cohort-based structure and the uncertainty of input parameters in mathematical models. Compared to no screening over 35 years follow-up, age-based screening prevented the most deaths from prostate cancer (39,272, 95% uncertainty interval [UI]: 16,792-59,685) at the expense of 94,831 (95% UI: 84,827-105,630) overdiagnosed cancers. Age-based screening was the least cost-effective strategy studied. The greatest number of quality-adjusted life-years (QALYs) was generated by risk-based screening at a 10-year absolute risk threshold of 4%. At this threshold, risk-based screening led to one-third fewer overdiagnosed cancers (64,384, 95% UI: 57,382-72,050) but averted 6.3% fewer (9,695, 95% UI: 2,853-15,851) deaths from prostate cancer by comparison with age-based screening. Relative to no screening, risk-based screening at a 4% 10-year absolute risk threshold was cost-effective in 48.4% and 57.4% of the simulations at willingness-to-pay thresholds of GBP20,000 (US$26,000) and 30,000 ($39,386) per QALY, respectively. The cost-effectiveness of risk-tailored screening improved as the threshold rose. Conclusions Based on the results of this modelling study, offering screening to men at higher risk could potentially reduce overdiagnosis and improve the benefit-harm tradeoff and the cost-effectiveness of a prostate cancer screening program. The optimal threshold will depend on societal judgements of the appropriate balance of benefits-harms and cost-effectiveness. Copyright: ÃƒÆ’Ã¢â‚¬Å¡Ãƒâ€šÃ‚Â© 2019 Callender et al. This is an open access article distributed under the terms of the Creative Commons Attribution License, which permits unrestricted use, distribution, and reproduction in any medium, provided the original author and source are credited. | E9: FALSE | F9: Focuses on cost-effectiveness, not explicit budget reduction. | G9: has_baseline_and_counterfactual | H9: 0.8
A10: J583 | B10: 2019 | C10: Community pharmacy personnel interventions for smoking cessation | D10: - Background Community pharmacists could provide effective smoking cessation treatment because they offer easy access to members of the community. They are well placed to provide both advice on the correct use of smoking cessation products and behavioural support to aid smoking cessation. Objectives To assess the effectiveness of interventions delivered by community pharmacy personnel to assist people to stop smoking, with or without concurrent use of pharmacotherapy. Search methods We searched the Cochrane Tobacco Addiction Group Specialised Register, along with clinicaltrials.gov and the ICTRP, for smoking cessation studies conducted in a community pharmacy setting, using the search terms pharmacist* or pharmacy or pharmacies. Date of the most recent search: January 2019. Selection criteria Randomised controlled trials of interventions delivered by community pharmacy personnel to promote smoking cessation amongst their clients who were smokers, compared with usual pharmacy support or any less intensive programme. The main outcome measure was smoking cessation rates at six months or more after the start of the intervention. Data collection and analysis We used standard methodological procedures expected by Cochrane for study screening, data extraction and management. We conducted a metaÃƒÆ’Ã‚Â¢ÃƒÂ¢Ã¢â‚¬Å¡Ã‚Â¬Ãƒâ€šÃ‚Âanalysis using a MantelÃƒÆ’Ã‚Â¢ÃƒÂ¢Ã¢â‚¬Å¡Ã‚Â¬Ãƒâ€šÃ‚ÂHaenszel randomÃƒÆ’Ã‚Â¢ÃƒÂ¢Ã¢â‚¬Å¡Ã‚Â¬Ãƒâ€šÃ‚Âeffects model to generate risk ratios (RRs) and 95% confidence intervals (CIs). Main results We identified seven studies including 1774 participants. We judged three studies to be at high risk of bias and four to be at unclear risk. Each study provided faceÃƒÆ’Ã‚Â¢ÃƒÂ¢Ã¢â‚¬Å¡Ã‚Â¬Ãƒâ€šÃ‚ÂtoÃƒÆ’Ã‚Â¢ÃƒÂ¢Ã¢â‚¬Å¡Ã‚Â¬Ãƒâ€šÃ‚Âface behavioural support delivered by pharmacy staff, and required pharmacy personnel training. Typically such programmes comprised support starting before quit day and continuing with weekly appointments for several weeks afterwards. Comparators were either minimal or less intensive behavioural support for smoking cessation, typically comprising a few minutes of oneÃƒÆ’Ã‚Â¢ÃƒÂ¢Ã¢â‚¬Å¡Ã‚Â¬Ãƒâ€šÃ‚Âoff advice on how to quit. Participants in both intervention and control arms received equivalent smoking cessation pharmacotherapy in all but one study. All studies took place in highÃƒÆ’Ã‚Â¢ÃƒÂ¢Ã¢â‚¬Å¡Ã‚Â¬Ãƒâ€šÃ‚Âincome countries, and recruited participants visiting pharmacies. We pooled six studies of 1614 participants and detected a benefit of more intensive behavioural smoking cessation interventions delivered by community pharmacy personnel compared with less intensive cessation interventions at longest followÃƒÆ’Ã‚Â¢ÃƒÂ¢Ã¢â‚¬Å¡Ã‚Â¬Ãƒâ€šÃ‚Âup (RR 2.30, 95% CI 1.33 to 3.97; I 2 = 54%; lowÃƒÆ’Ã‚Â¢ÃƒÂ¢Ã¢â‚¬Å¡Ã‚Â¬Ãƒâ€šÃ‚Âcertainty evidence). Authors' conclusions Community pharmacists can provide effective behavioural support to people trying to stop smoking. However, this conclusion is based on lowÃƒÆ’Ã‚Â¢ÃƒÂ¢Ã¢â‚¬Å¡Ã‚Â¬Ãƒâ€šÃ‚Âcertainty evidence, limited by risk of bias and imprecision. Further research could change this conclusion. Plain language summary Does quitÃƒÆ’Ã‚Â¢ÃƒÂ¢Ã¢â‚¬Å¡Ã‚Â¬Ãƒâ€šÃ‚Âsmoking support delivered by community pharmacy staff help people to stop smoking? Background Tobacco smoking is the leading cause of preventable death and disease worldwide. Community pharmacists are respected healthcare professionals who provide easily accessible and convenient healthcare services to their communities, and they are well placed to provide their clients with help to quit smoking. Indeed, many governments recognise community pharmacies as a useful way of delivering many healthcare services. However, we need evidence that these services are effective before we develop them more widely. Study characteristics We searched for relevant studies in January 2019, and found seven studies including 1774 people. Three studies took place in the UK, and one each in Australia, United States, Qatar, and Italy. Each study provided faceÃƒÆ’Ã‚Â¢ÃƒÂ¢Ã¢â‚¬Å¡Ã‚Â¬Ãƒâ€šÃ‚ÂtoÃƒÆ’Ã‚Â¢ÃƒÂ¢Ã¢â‚¬Å¡Ã‚Â¬Ãƒâ€šÃ‚Âface behavioural support delivered by pharmacy staff, who received specific training. Studies compared the structured programme to less intensive support to stop smoking. Key results We found evidence that more intensive structured care given by community pharmacy staff probably helps more people to quit smoking than less intensive support to quit. Qualit of the evidence We found lowÃƒÆ’Ã‚Â¢ÃƒÂ¢Ã¢â‚¬Å¡Ã‚Â¬Ãƒâ€šÃ‚Âquality evidence that community pharmacy support helps people to quit smoking. Limitations of the evidence came from potential problems with the ways some of the studies were carried out and the low numbers of people who quit smoking across the included studies, which means we are not sure how effective these programmes really are. | E10: FALSE | F10: Focuses on effectiveness, not budget impact. | G10: no_cost_shift_or_harm | H10: 0.9
A11: J587 | B11: 2019 | C11: Digital and online symptom checkers and assessment services for urgent care to inform a new digital platform: a systematic review | D11: <b>BACKGROUND</b>: Digital and online symptom checkers and assessment services are used by patients seeking guidance about health problems. NHS England is planning to introduce a digital platform (NHS111 Online) to operate alongside the NHS111 urgent-care telephone service. This review focuses on digital and online symptom checkers for urgent health problems._x000D_ <b>OBJECTIVES</b>: This systematic review was commissioned to provide NHS England with an independent review of previous research in this area to inform strategic decision-making and service design._x000D_ <b>DATA SOURCES</b>: Focused searches of seven bibliographic databases were performed and supplemented by phrase searching for names of symptom checker systems and citation searches of key included studies. The bibliographic databases searched were MEDLINE, EMBASE, The Cochrane Library, CINAHL (Cumulative Index to Nursing and Allied Health Literature), HMIC (Health Management Information Consortium), Web of Science and the Association of Computing Machinery (ACM) Digital Library, from inception up to April 2018._x000D_ <b>REVIEW METHODS</b>: Brief inclusion criteria were (1) population - general population seeking information online or digitally to address an urgent health problem; (2) intervention - any online or digital service designed to assess symptoms, provide health advice and direct patients to appropriate services; and (3) comparator - telephone or face-to-face assessment, comparative performance in tests or simulations (studies with no comparator were included if they reported relevant outcomes). Outcomes of interest included safety, clinical effectiveness, costs or cost-effectiveness, diagnostic and triage accuracy, use of and contacts with health services, compliance with advice received, patient/carer satisfaction, and equity and inclusion. Inclusion was not restricted by study design. Screening studies for inclusion, data extraction and quality assessment were carried out by one reviewer with a sample checked for accuracy and consistency. Final decisions on study inclusion were taken by consensus of the review team. A narrative synthesis of the included studies was performed and structured around the predefined research questions and key outcomes. The overall strength of evidence for each outcome was classified as 'stronger', 'weaker', 'conflicting' or 'insufficient', based on study numbers and design._x000D_ <b>RESULTS</b>: In total, 29 publications describing 27 studies were included. Studies were diverse in their design and methodology. The overall strength of the evidence was weak because it was largely based on observational studies and with a substantial component of non-peer-reviewed grey literature. There was little evidence to suggest that symptom checkers are unsafe, but studies evaluating their safety were generally short term and small scale. Diagnostic accuracy was highly variable between different systems but was generally low. Algorithm-based triage tended to be more risk averse than that of health professionals. Inconsistent evidence was found on effects on service use. There was very limited evidence on patients' reactions to online triage advice. The studies showed that younger and more highly educated people are more likely to use these services. Study participants generally expressed high levels of satisfaction with digital and online triage services, albeit in uncontrolled studies._x000D_ <b>LIMITATIONS</b>: Findings from symptom checker systems for specific conditions may not be applicable to more general systems and vice versa. Studies of symptom checkers as part of electronic consultation systems in general practice were also included, which is a slightly different setting from a general 'digital 111' service. Most studies were screened by one reviewer._x000D_ <b>CONCLUSIONS</b>: Major uncertainties surround the probable impact of digital 111 services on most outcomes. It will be important to monitor and evaluate the services using all available data sources and by commissioning high-quality research._x000D_ <b>FUTURE WORK</b>: Priorities for research include comparisons of different systems, rigorous economic evaluations and investigations of patient pathways._x000D_ <b>STUDY REGISTRATION</b>: The study is registered as PROSPERO CRD42018093564._x000D_ <b>FUNDING</b>: The National Institute for Health Research Health Services and Delivery Research programme. | E11: FALSE | F11: No explicit budget reduction or cash-releasing benefits mentioned. | H11: 0.9
A12: J2833 | B12: 2021 | C12: Mobile phoneÃƒÆ’Ã‚Â¢ÃƒÂ¢Ã¢â‚¬Å¡Ã‚Â¬Ãƒâ€šÃ‚Âbased interventions for improving adherence to medication prescribed for the primary prevention of cardiovascular disease in adults | D12: - Background Cardiovascular disease (CVD) is a major cause of disability and mortality globally. Premature fatal and nonÃƒÆ’Ã‚Â¢ÃƒÂ¢Ã¢â‚¬Å¡Ã‚Â¬Ãƒâ€šÃ‚Âfatal CVD is considered to be largely preventable through the control of risk factors by lifestyle modifications and preventive medication. LipidÃƒÆ’Ã‚Â¢ÃƒÂ¢Ã¢â‚¬Å¡Ã‚Â¬Ãƒâ€šÃ‚Âlowering and antihypertensive drug therapies for primary prevention are costÃƒÆ’Ã‚Â¢ÃƒÂ¢Ã¢â‚¬Å¡Ã‚Â¬Ãƒâ€šÃ‚Âeffective in reducing CVD morbidity and mortality among highÃƒÆ’Ã‚Â¢ÃƒÂ¢Ã¢â‚¬Å¡Ã‚Â¬Ãƒâ€šÃ‚Ârisk people and are recommended by international guidelines. However, adherence to medication prescribed for the prevention of CVD can be poor. Approximately 9% of CVD cases in the EU are attributed to poor adherence to vascular medications. LowÃƒÆ’Ã‚Â¢ÃƒÂ¢Ã¢â‚¬Å¡Ã‚Â¬Ãƒâ€šÃ‚Âcost, scalable interventions to improve adherence to medications for the primary prevention of CVD have potential to reduce morbidity, mortality and healthcare costs associated with CVD. Objectives To establish the effectiveness of interventions delivered by mobile phone to improve adherence to medication prescribed for the primary prevention of CVD in adults. Search methods We searched CENTRAL, MEDLINE, Embase, and two other databases on 7 January 2020. We also searched two clinical trials registers on 5 February 2020. We searched reference lists of relevant papers. We applied no language or date restrictions. Selection criteria We included randomised controlled trials investigating interventions delivered wholly or partly by mobile phones to improve adherence to cardiovascular medications prescribed for the primary prevention of CVD. We only included trials with a minimum of oneÃƒÆ’Ã‚Â¢ÃƒÂ¢Ã¢â‚¬Å¡Ã‚Â¬Ãƒâ€šÃ‚Âyear followÃƒÆ’Ã‚Â¢ÃƒÂ¢Ã¢â‚¬Å¡Ã‚Â¬Ãƒâ€šÃ‚Âup in order that the outcome measures related to longerÃƒÆ’Ã‚Â¢ÃƒÂ¢Ã¢â‚¬Å¡Ã‚Â¬Ãƒâ€šÃ‚Âterm, sustained medication adherence behaviours and outcomes. Eligible comparators were usual care or control groups receiving no mobile phoneÃƒÆ’Ã‚Â¢ÃƒÂ¢Ã¢â‚¬Å¡Ã‚Â¬Ãƒâ€šÃ‚Âdelivered component of the intervention. Data collection and analysis We used standard methodological procedures recommended by Cochrane. The main outcomes of interest were objective measures of medication adherence (blood pressure (BP) and cholesterol), CVD events, and adverse events. We contacted study authors for further information when this was not reported. Main results We included 14 trials with 25,633 randomised participants. Participants were recruited from communityÃƒÆ’Ã‚Â¢ÃƒÂ¢Ã¢â‚¬Å¡Ã‚Â¬Ãƒâ€šÃ‚Âbased primary and tertiary care or outpatient clinics. The interventions varied widely from those delivered solely through short messaging service (SMS) to those involving a combination of modes of delivery, such as SMS in addition to healthcare worker training, faceÃƒÆ’Ã‚Â¢ÃƒÂ¢Ã¢â‚¬Å¡Ã‚Â¬Ãƒâ€šÃ‚ÂtoÃƒÆ’Ã‚Â¢ÃƒÂ¢Ã¢â‚¬Å¡Ã‚Â¬Ãƒâ€šÃ‚Âface counselling, electronic pillboxes, written materials, and home blood pressure monitors. Some interventions only targeted medication adherence, while others additionally targeted lifestyle changes such as diet and exercise. Due to heterogeneity in the nature and delivery of the interventions and study populations, we reported most results narratively, with the exception of two trials which were similar enough to meaningfully pool in metaÃƒÆ’Ã‚Â¢ÃƒÂ¢Ã¢â‚¬Å¡Ã‚Â¬Ãƒâ€šÃ‚Âanalyses. The body of evidence for the effect of mobile phoneÃƒÆ’Ã‚Â¢ÃƒÂ¢Ã¢â‚¬Å¡Ã‚Â¬Ãƒâ€šÃ‚Âbased interventions on objective outcomes of adherence (BP and cholesterol) was of low certainty, due to most trials being at high risk of bias, and inconsistency in outcome effects. Two trials were at low risk of bias. Among five trials (total study enrolment: 5441 participants) recording lowÃƒÆ’Ã‚Â¢ÃƒÂ¢Ã¢â‚¬Å¡Ã‚Â¬Ãƒâ€šÃ‚Âdensity lipoprotein cholesterol (LDLÃƒÆ’Ã‚Â¢ÃƒÂ¢Ã¢â‚¬Å¡Ã‚Â¬Ãƒâ€šÃ‚ÂC), two studies found evidence for a small beneficial intervention effect on reducing LDLÃƒÆ’Ã‚Â¢ÃƒÂ¢Ã¢â‚¬Å¡Ã‚Â¬Ãƒâ€šÃ‚ÂC (ÃƒÆ’Ã‚Â¢Ãƒâ€¹Ã¢â‚¬Â ÃƒÂ¢Ã¢â€šÂ¬Ã¢â€žÂ¢5.30 mg/dL, 95% confidence interval (CI) ÃƒÆ’Ã‚Â¢Ãƒâ€¹Ã¢â‚¬Â ÃƒÂ¢Ã¢â€šÂ¬Ã¢â€žÂ¢8.30 to ÃƒÆ’Ã‚Â¢Ãƒâ€¹Ã¢â‚¬Â ÃƒÂ¢Ã¢â€šÂ¬Ã¢â€žÂ¢2.30; and ÃƒÆ’Ã‚Â¢Ãƒâ€¹Ã¢â‚¬Â ÃƒÂ¢Ã¢â€šÂ¬Ã¢â€žÂ¢9.20 mg/dL, 95% CI ÃƒÆ’Ã‚Â¢Ãƒâ€¹Ã¢â‚¬Â ÃƒÂ¢Ã¢â€šÂ¬Ã¢â€žÂ¢17.70 to ÃƒÆ’Ã‚Â¢Ãƒâ€¹Ã¢â‚¬Â ÃƒÂ¢Ã¢â€šÂ¬Ã¢â€žÂ¢0.70). The other three studies found results varying from a small reduction (ÃƒÆ’Ã‚Â¢Ãƒâ€¹Ã¢â‚¬Â ÃƒÂ¢Ã¢â€šÂ¬Ã¢â€žÂ¢7.7 mg/dL) to a small increase in LDLÃƒÆ’Ã‚Â¢ÃƒÂ¢Ã¢â‚¬Å¡Ã‚Â¬Ãƒâ€šÃ‚ÂC (0.77 mg/dL). All of which had wide confidence intervals that included no effect. Across 13 studies (25,166 participants) measuring systolic blood pressure, effect estimates ranged from a large reduction (MD ÃƒÆ’Ã‚Â¢Ãƒâ€¹Ã¢â‚¬Â ÃƒÂ¢Ã¢â€šÂ¬Ã¢â€žÂ¢12.45 mmHg, 95% CI ÃƒÆ’Ã‚Â¢Ãƒâ€¹Ã¢â‚¬Â ÃƒÂ¢Ã¢â€šÂ¬Ã¢â€žÂ¢15.02 to ÃƒÆ’Ã‚Â¢Ãƒâ€¹Ã¢â‚¬Â ÃƒÂ¢Ã¢â€šÂ¬Ã¢â€žÂ¢9.88) to a small increase (MD 2.80 mmHg, 95% CI 0.30 to 5.30). We found a similar range of effect estimates for diastolic BP, ranging from ÃƒÆ’Ã‚Â¢Ãƒâ€¹Ã¢â‚¬Â ÃƒÂ¢Ã¢â€šÂ¬Ã¢â€žÂ¢12.23 mmHg (95% CI ÃƒÆ’Ã‚Â¢Ãƒâ€¹Ã¢â‚¬Â ÃƒÂ¢Ã¢â€šÂ¬Ã¢â€žÂ¢14.03 to ÃƒÆ’Ã‚Â¢Ãƒâ€¹Ã¢â‚¬Â ÃƒÂ¢Ã¢â€šÂ¬Ã¢â€žÂ¢10.43) to 1.64 mmHg (95% CI ÃƒÆ’Ã‚Â¢Ãƒâ€¹Ã¢â‚¬Â ÃƒÂ¢Ã¢â€šÂ¬Ã¢â€žÂ¢0.55 to 3.83) (11 trials, 19,716 participants). Four trials showed intervention benefits for systolic and diastolic BP with confidence intervals excluding no effect, and among these were all three of the trials evaluating selfÃƒÆ’Ã‚Â¢ÃƒÂ¢Ã¢â‚¬Å¡Ã‚Â¬Ãƒâ€šÃ‚Âmonitoring of blood pressure with mobile phoneÃƒÆ’Ã‚Â¢ÃƒÂ¢Ã¢â‚¬Å¡Ã‚Â¬Ãƒâ€šÃ‚Âbased telemedicine. The fourth trial included SMS and provider support (with additional varied features). Seven studies (19,185 participants) reported 'controlled' BP as an outcome, and intervention effect estimates varied from negligible effects (odds ratio (OR) 1.01, 95% CI 0.76 to 1.34) to large improvements in BP control (OR 2.41, 95% CI: 1.57 to 3.68). The three trials of clinician training or decision support combined with SMS (with additional varied features) had confidence intervals encompassing benefits and harms, with point estimates close to zero. Pooled analyses of the two trials of interventions solely delivered through SMS were indicative of little or no beneficial intervention effect on systolic BP (MD ÃƒÆ’Ã‚Â¢Ãƒâ€¹Ã¢â‚¬Â ÃƒÂ¢Ã¢â€šÂ¬Ã¢â€žÂ¢1.55 mmHg, 95% CI ÃƒÆ’Ã‚Â¢Ãƒâ€¹Ã¢â‚¬Â ÃƒÂ¢Ã¢â€šÂ¬Ã¢â€žÂ¢3.36 to 0.25; I 2 = 0%) and small increases in controlled BP (OR 1.32, 95% CI 1.06 to 1.65; I 2 = 0%). Based on four studies (12,439 participants), there was very lowÃƒÆ’Ã‚Â¢ÃƒÂ¢Ã¢â‚¬Å¡Ã‚Â¬Ãƒâ€šÃ‚Âcertainty evidence (downgraded twice for imprecision and once for risk of bias) relating to the intervention effect on combined (fatal and nonÃƒÆ’Ã‚Â¢ÃƒÂ¢Ã¢â‚¬Å¡Ã‚Â¬Ãƒâ€šÃ‚Âfatal) CVD events. Two studies (2535 participants) provided lowÃƒÆ’Ã‚Â¢ÃƒÂ¢Ã¢â‚¬Å¡Ã‚Â¬Ãƒâ€šÃ‚Âcertainty evidence for the effect of the intervention on cognitive outcomes, with little or no difference between trial arms for perceived quality of care and satisfaction with treatment. There was moderateÃƒÆ’Ã‚Â¢ÃƒÂ¢Ã¢â‚¬Å¡Ã‚Â¬Ãƒâ€šÃ‚Âcertainty evidence (downgraded due to risk of bias) that the interventions did not cause harm, based on six studies (8285 participants). Three studies reported no adverse events attributable to the intervention. One study reported no difference between groups in experience of adverse effects of statins, and that no participants reported interventionÃƒÆ’Ã‚Â¢ÃƒÂ¢Ã¢â‚¬Å¡Ã‚Â¬Ãƒâ€šÃ‚Ârelated adverse events. One study stated that potential side effects were similar between groups. One study reported a similar number of deaths in each arm, but did not provide further information relating to potential adverse events. Authors' conclusions There is lowÃƒÆ’Ã‚Â¢ÃƒÂ¢Ã¢â‚¬Å¡Ã‚Â¬Ãƒâ€šÃ‚Âcertainty evidence on the effects of mobile phoneÃƒÆ’Ã‚Â¢ÃƒÂ¢Ã¢â‚¬Å¡Ã‚Â¬Ãƒâ€šÃ‚Âdelivered interventions to increase adherence to medication prescribed for the primary prevention of CVD. Trials of BP selfÃƒÆ’Ã‚Â¢ÃƒÂ¢Ã¢â‚¬Å¡Ã‚Â¬Ãƒâ€šÃ‚Âmonitoring with mobileÃƒÆ’Ã‚Â¢ÃƒÂ¢Ã¢â‚¬Å¡Ã‚Â¬Ãƒâ€šÃ‚Âphone telemedicine support reported modest benefits. One trial at low risk of bias reported modest reductions in LDL cholesterol but no benefits for BP. There is moderateÃƒÆ’Ã‚Â¢ÃƒÂ¢Ã¢â‚¬Å¡Ã‚Â¬Ãƒâ€šÃ‚Âcertainty evidence that these interventions do not result in harm. Further trials of these interventions are warranted. Plain language summary Interventions delivered by mobile phone to help people adhere to medication to prevent heart and circulatory disease Review question We reviewed the evidence on the effect of interventions delivered by mobile phone to help people in taking their medication to prevent cardiovascular disease (for example, heart attacks and strokes). Background Around 17.6 million people die from cardiovascular disease every year. Medications can help to prevent cardiovascular disease, but many people who have been given these medications do not take them as often or as consistently as recommended. This means that the medication will not work as well as it could to prevent cardiovascular disease. Interventions delivered through mobile phones, for example, prompting by text messaging, may be a lowÃƒÆ’Ã‚Â¢ÃƒÂ¢Ã¢â‚¬Å¡Ã‚Â¬Ãƒâ€šÃ‚Âcost way to help people to take their medication as recommended. Study characteristics The evidence is up to date to January 2020. We found 14 studies that tested interventions delivered at least partly by mobile phone, which followed up participants for at least 12 months. Key results We were not able to combine the results of most of the trials, because the interventions were very different. Two studies were at low risk of bias and 12 were at high risk of bias. T e effects of the interventions were inconsistent across studies, and so we are not confident about their findings. SelfÃƒÆ’Ã‚Â¢ÃƒÂ¢Ã¢â‚¬Å¡Ã‚Â¬Ãƒâ€šÃ‚Âmonitoring of blood pressure plus telemedicine support by mobile phone may improve blood pressure control, but we are not confident about the findings due to trials being at risk of bias. Interventions delivered by text message alone may have little or no effect on blood pressure control. Interventions which included text messages and clinician training or clinician decision support (with or without additional features) may have little or no effect on blood pressure or cholesterol. The effects of the interventions which included text messages and provider support (with or without other features) were inconsistent across studies, and so we are not confident about their findings. We are uncertain about the effects of apps held by the patient or apps with additional provider support. Some interventions delivered by mobile phone may help people to take their medication, but the benefits are small or modest. Some trials found that the interventions did not have any beneficial effect. There was no evidence to suggest that these types of interventions caused harm. | E12: FALSE | F12: Focus on adherence improvement, not explicit budget reduction. | G12: no_cost_shift_or_harm | H12: 0.8
